<?xml version="1.0" encoding="utf-8"?>
<!-- This URDF was automatically created by SolidWorks to URDF Exporter! Originally created by Stephen Brawner (brawner@gmail.com) 
     Commit Version: 1.6.0-4-g7f85cfe  Build Version: 1.6.7995.38578
     For more information, please see http://wiki.ros.org/sw_urdf_exporter -->
<robot
  name="Gento Luna_URDF">
  <link
    name="base_link">
    <inertial>
      <origin
        xyz="-0.057032 -2.1661E-05 0.069035"
        rpy="0 0 0" />
      <mass
        value="90.8" />
      <inertia
        ixx="0.030091"
        ixy="1.852E-07"
        ixz="0.0008246"
        iyy="0.027232"
        iyz="-5.9854E-07"
        izz="0.021579" />
    </inertial>
    <visual>
      <origin
        xyz="0 0 0"
        rpy="0 0 0" />
      <geometry>
        <mesh
          filename="package://marvin_description/meshes/Gento_Luna/Underpan_Base_link.STL" />
      </geometry>
      <material
        name="">
        <color
          rgba="1 0 0 1" />
      </material>
    </visual>
    <collision>
      <origin
        xyz="0 0 0"
        rpy="0 0 0" />
      <geometry>
        <mesh
          filename="package://marvin_description/meshes/Gento_Luna/Underpan_Base_link.STL" />
      </geometry>
    </collision>
  </link>
  <link
    name="Leg_J1_Link">
    <inertial>
      <origin
        xyz="-0.00305605 0.11879615 0.00090574"
        rpy="0 0 0" />
      <mass
        value="6.042" />
      <inertia
        ixx="0.13541951"
        ixy="-0.00304381"
        ixz="0.00002039"
        iyy="0.011899"
        iyz="0.00029731"
        izz="0.13138323" />
    </inertial>
    <visual>
      <origin
        xyz="0 0 0"
        rpy="0 0 0" />
      <geometry>
        <mesh
          filename="package://marvin_description/meshes/Gento_Luna/Leg_J1_Link.STL" />
      </geometry>
      <material
        name="">
        <color
          rgba="0 1 0 1" />
      </material>
    </visual>
    <collision>
      <origin
        xyz="0 0 0"
        rpy="0 0 0" />
      <geometry>
        <mesh
          filename="package://marvin_description/meshes/Gento_Luna/Leg_J1_Link.STL" />
      </geometry>
    </collision>
  </link>
  <joint
    name="Leg_J1_Joint"
    type="revolute">
    <origin
      xyz="0 0 0.1"
      rpy="1.5708 0 1.5708" />
    <parent
      link="base_link" />
    <child
      link="Leg_J1_Link" />
    <axis
      xyz="0 0 1" />
    <limit
      lower="-0.191986218"
      upper="0.191986218"
      effort="217"
      velocity="3.560471674" />
  </joint>
  <link
    name="Leg_J2_Link">
    <inertial>
      <origin
        xyz="-0.00305605 0.11879615 0.00090574"
        rpy="0 0 0" />
      <mass
        value="6.04185968" />
      <inertia
        ixx="0.43952038"
        ixy="0.00264772"
        ixz="0.00003002"
        iyy="0.02664581"
        iyz="0.01501651"
        izz="0.43711033" />
    </inertial>
    <visual>
      <origin
        xyz="0 0 0"
        rpy="0 0 0" />
      <geometry>
        <mesh
          filename="package://marvin_description/meshes/Gento_Luna/Leg_J2_Link.STL" />
      </geometry>
      <material
        name="">
        <color
          rgba="0 0 1 1" />
      </material>
    </visual>
    <collision>
      <origin
        xyz="0 0 0"
        rpy="0 0 0" />
      <geometry>
        <mesh
          filename="package://marvin_description/meshes/Gento_Luna/Leg_J2_Link.STL" />
      </geometry>
    </collision>
  </link>
  <joint
    name="Leg_J2_Joint"
    type="revolute">
    <origin
      xyz="0 0.165 0"
      rpy="0 -1.5708 0" />
    <parent
      link="Leg_J1_Link" />
    <child
      link="Leg_J2_Link" />
    <axis
      xyz="0 0 1" />
    <limit
      lower="-1.570796327"
      upper="1.570796327"
      effort="217"
      velocity="3.560471674" />
  </joint>
  <link
    name="Leg_J3_Link">
    <inertial>
      <origin
        xyz="-0.00357006 0.14573557 -0.00024996"
        rpy="0 0 0" />
      <mass
        value="4.67121672" />
      <inertia
        ixx="0.01093259"
        ixy="0.00003321"
        ixz="-0.00007126"
        iyy="0.03862616"
        iyz="-0.00000616"
        izz="0.03693718" />
    </inertial>
    <visual>
      <origin
        xyz="0 0 0"
        rpy="0 0 0" />
      <geometry>
        <mesh
          filename="package://marvin_description/meshes/Gento_Luna/Leg_J3_Link.STL" />
      </geometry>
      <material
        name="">
        <color
          rgba="1 0 0 1" />
      </material>
    </visual>
    <collision>
      <origin
        xyz="0 0 0"
        rpy="0 0 0" />
      <geometry>
        <mesh
          filename="package://marvin_description/meshes/Gento_Luna/Leg_J3_Link.STL" />
      </geometry>
    </collision>
  </link>
  <joint
    name="Leg_J3_Joint"
    type="revolute">
    <origin
      xyz="0 0.3 0"
      rpy="0 0 0" />
    <parent
      link="Leg_J2_Link" />
    <child
      link="Leg_J3_Link" />
    <axis
      xyz="0 0 1" />
    <limit
      lower="-2.443460953"
      upper="1.047197551"
      effort="217"
      velocity="3.560471674" />
  </joint>
  <link
    name="Leg_J4_Link">
    <inertial>
      <origin
          xyz="-0.03690660 -0.00007427 0.301019860"
        rpy="0 0 0" />
      <mass
        value="5.90046349" />
      <inertia
        ixx="0.01093259"
        ixy="0.00003321"
        ixz="-0.00007126"
        iyy="0.03862616"
        iyz="-0.00000616"
        izz="0.03693718" />
    </inertial>
    <visual>
      <origin
        xyz="0 0 0"
        rpy="0 0 0" />
      <geometry>
        <mesh
          filename="package://marvin_description/meshes/Gento_Luna/Leg_J4_Link.STL" />
      </geometry>
      <material
        name="">
        <color
          rgba="0 1 0 1" />
      </material>
    </visual>
    <collision>
      <origin
        xyz="0 0 0"
        rpy="0 0 0" />
      <geometry>
        <mesh
          filename="package://marvin_description/meshes/Gento_Luna/Leg_J4_Link.STL" />
      </geometry>
    </collision>
  </link>
  <joint
    name="Leg_J4_Joint"
    type="revolute">
    <origin
      xyz="0 0.3 0"
      rpy="0 0 0" />
    <parent
      link="Leg_J3_Link" />
    <child
      link="Leg_J4_Link" />
    <axis
      xyz="0 0 1" />
    <limit
      lower="-0.959931089"
      upper="1.919862177"
      effort="108"
      velocity="3.560471674" />
  </joint>
  <link
    name="Leg_J5_Link">
    <inertial>
      <origin
        xyz="-0.00154757 0.12766899 -0.01565105"
        rpy="0 0 0" />
      <mass
        value="3.76177572" />
      <inertia
        ixx="0.09652163"
        ixy="-0.00089293"
        ixz="-0.00004906"
        iyy="0.02155599"
        iyz="-0.00379500"
        izz="0.08166085" />
    </inertial>
    <visual>
      <origin
        xyz="0 0 0"
        rpy="0 0 0" />
      <geometry>
        <mesh
          filename="package://marvin_description/meshes/Gento_Luna/Leg_J5_Link.STL" />
      </geometry>
      <material
        name="">
        <color
          rgba="0 0 1 1" />
      </material>
    </visual>
    <collision>
      <origin
        xyz="0 0 0"
        rpy="0 0 0" />
      <geometry>
        <mesh
          filename="package://marvin_description/meshes/Gento_Luna/Leg_J5_Link.STL" />
      </geometry>
    </collision>
  </link>
  <joint
    name="Leg_J5_Joint"
    type="revolute">
    <origin
      xyz="0 0 0"
      rpy="0 1.5708 0" />
    <parent
      link="Leg_J4_Link" />
    <child
      link="Leg_J5_Link" />
    <axis
      xyz="0 0 1" />
    <limit
      lower="-0.523598776"
      upper="0.523598776"
      effort="108"
      velocity="5.235987756" />
  </joint>
  <link
    name="Leg_J6_Link">
    <inertial>
      <origin
        xyz="-0.00252318 0.00023889 0.35352016"
        rpy="0 0 0" />
      <mass
        value="7.69392497" />
      <inertia
        ixx="1.05947349"
        ixy="0.00039762"
        ixz="-0.00299102"
        iyy="1.04629026"
        iyz="0.00056280"
        izz="0.06683072" />
    </inertial>
    <visual>
      <origin
        xyz="0 0 0"
        rpy="0 0 0" />
      <geometry>
        <mesh
          filename="package://marvin_description/meshes/Gento_Luna/Leg_J6_Link.STL" />
      </geometry>
      <material
        name="">
        <color
          rgba="1 0 0 1" />
      </material>
    </visual>
    <collision>
      <origin
        xyz="0 0 0"
        rpy="0 0 0" />
      <geometry>
        <mesh
          filename="package://marvin_description/meshes/Gento_Luna/Leg_J6_Link.STL" />
      </geometry>
    </collision>
  </link>
  <joint
    name="Leg_J6_Joint"
    type="revolute">
    <origin
      xyz="0 0 0"
      rpy="-1.5708 -1.5708 0" />
    <parent
      link="Leg_J5_Link" />
    <child
      link="Leg_J6_Link" />
    <axis
      xyz="0 0 1" />
    <limit
      lower="-2.967059728"
      upper="2.967059728"
      effort="108"
      velocity="5.235987756" />
  </joint>
  <link
    name="Arm_R1_Link">
    <inertial>
      <origin
         xyz="-3.3175e-04 -4.26687e-03 -3.522466e-02"
        rpy="0 0 0" />
      <mass
        value="1.537551" />
      <inertia
        ixx="3.66914e-03"
        ixy="1.77e-06"
        ixz="1.342e-05"
        iyy="3.94529e-03"
        iyz="-2.3437e-04"
        izz="1.31774e-03" />
    </inertial>
    <visual>
      <origin
        xyz="0 0 0"
        rpy="0 0 0" />
      <geometry>
        <mesh
          filename="package://marvin_description/meshes/Gento_Luna/Arm_R1_Link.STL" />
      </geometry>
      <material
        name="">
        <color
          rgba="0 1 0 1" />
      </material>
    </visual>
    <collision>
      <origin
        xyz="0 0 0"
        rpy="0 0 0" />
      <geometry>
        <mesh
          filename="package://marvin_description/meshes/Gento_Luna/Arm_R1_Link.STL" />
      </geometry>
    </collision>
  </link>
  <joint
    name="Arm_R1_Joint"
    type="revolute">
    <origin
      xyz="0 -0.2146 0.3915"
      rpy="1.5708 0 0" />
    <parent
      link="Leg_J6_Link" />
    <child
      link="Arm_R1_Link" />
    <axis
      xyz="0 0 1" />
    <limit
      lower="-3.0194"
      upper="3.0194"
      effort="35"
      velocity="3.1416" />
  </joint>
  <link
    name="Arm_R2_Link">
    <inertial>
      <origin
         xyz="-1.6285e-04 4.983697e-02 -8.33367e-03"
        rpy="0 0 0" />
      <mass
        value="1.540624" />
      <inertia
        ixx="5.98937e-03"
        ixy="1.663e-05"
        ixz="8.58e-06"
        iyy="1.83242e-03"
        iyz="6.4328e-04"
        izz="5.64358e-03" />
    </inertial>
    <visual>
      <origin
        xyz="0 0 0"
        rpy="0 0 0" />
      <geometry>
        <mesh
          filename="package://marvin_description/meshes/Gento_Luna/Arm_R2_Link.STL" />
      </geometry>
      <material
        name="">
        <color
          rgba="0 0 1 1" />
      </material>
    </visual>
    <collision>
      <origin
        xyz="0 0 0"
        rpy="0 0 0" />
      <geometry>
        <mesh
          filename="package://marvin_description/meshes/Gento_Luna/Arm_R2_Link.STL" />
      </geometry>
    </collision>
  </link>
  <joint
    name="Arm_R2_Joint"
    type="revolute">
    <origin
      xyz="0 0 0"
      rpy="1.5708 0 0" />
    <parent
      link="Arm_R1_Link" />
    <child
      link="Arm_R2_Link" />
    <axis
      xyz="0 0 1" />
    <limit
      lower="-2.0595"
      upper="2.0595"
      effort="35"
      velocity="3.1416" />
  </joint>
  <link
    name="Arm_R3_Link">
    <inertial>
      <origin
        xyz="8.2949e-03 -4.11162e-03 -4.916618e-02"
        rpy="0 0 0" />
      <mass
        value="1.361743" />
      <inertia
        ixx="4.67364e-03"
        ixy="-5.704e-05"
        ixz="5.8882e-04"
        iyy="4.98053e-03"
        iyz="-2.7207e-04"
        izz="1.19672e-03" />
    </inertial>
    <visual>
      <origin
        xyz="0 0 0"
        rpy="0 0 0" />
      <geometry>
        <mesh
          filename="package://marvin_description/meshes/Gento_Luna/Arm_R3_Link.STL" />
      </geometry>
      <material
        name="">
        <color
          rgba="1 0 0 1" />
      </material>
    </visual>
    <collision>
      <origin
        xyz="0 0 0"
        rpy="0 0 0" />
      <geometry>
        <mesh
          filename="package://marvin_description/meshes/Gento_Luna/Arm_R3_Link.STL" />
      </geometry>
    </collision>
  </link>
  <joint
    name="Arm_R3_Joint"
    type="revolute">
    <origin
      xyz="0 0.264 0"
      rpy="-1.5708 0 0" />
    <parent
      link="Arm_R2_Link" />
    <child
      link="Arm_R3_Link" />
    <axis
      xyz="0 0 1" />
    <limit
       lower="-3.0194"
      upper="3.0194"
      effort="18"
      velocity="3.1416" />
  </joint>
  <link
    name="Arm_R4_Link">
    <inertial>
      <origin
       xyz="8.52387e-03 -3.857074e-02 -8.01541e-03"
        rpy="0 0 0" />
      <mass
        value="1.034295" />
      <inertia
        ixx="3.03957e-03"
        ixy="-3.7917e-04"
        ixz="6.787e-05"
        iyy="1.18553e-03"
        iyz="-3.1048e-04"
        izz="2.88173e-03" />
    </inertial>
    <visual>
      <origin
        xyz="0 0 0"
        rpy="0 0 0" />
      <geometry>
        <mesh
          filename="package://marvin_description/meshes/Gento_Luna/Arm_R4_Link.STL" />
      </geometry>
      <material
        name="">
        <color
          rgba="0 1 0 1" />
      </material>
    </visual>
    <collision>
      <origin
        xyz="0 0 0"
        rpy="0 0 0" />
      <geometry>
        <mesh
          filename="package://marvin_description/meshes/Gento_Luna/Arm_R4_Link.STL" />
      </geometry>
    </collision>
  </link>
  <joint
    name="Arm_R4_Joint"
    type="revolute">
    <origin
      xyz="0.018 0 0"
      rpy="-1.5708 0 -3.1416" />
    <parent
      link="Arm_R3_Link" />
    <child
      link="Arm_R4_Link" />
    <axis
      xyz="0 0 1" />
    <limit
      lower="-2.5307"
      upper="0.7854"
      effort="18"
      velocity="3.1416" />
  </joint>
  <link
    name="Arm_R5_Link">
    <inertial>
      <origin
         xyz="5.008e-04 -2.23923e-03 -9.253416e-02"
        rpy="0 0 0" />
      <mass
        value="1.000479" />
      <inertia
        ixx="2.17057e-03"
        ixy="-1.142e-05"
        ixz="6.68e-06"
        iyy="1.95131e-03"
        iyz="-3.059e-05"
        izz="8.4222e-04" />
    </inertial>
    <visual>
      <origin
        xyz="0 0 0"
        rpy="0 0 0" />
      <geometry>
        <mesh
          filename="package://marvin_description/meshes/Gento_Luna/Arm_R5_Link.STL" />
      </geometry>
      <material
        name="">
        <color
          rgba="0 0 1 1" />
      </material>
    </visual>
    <collision>
      <origin
        xyz="0 0 0"
        rpy="0 0 0" />
      <geometry>
        <mesh
          filename="package://marvin_description/meshes/Gento_Luna/Arm_R5_Link.STL" />
      </geometry>
    </collision>
  </link>
  <joint
    name="Arm_R5_Joint"
    type="revolute">
    <origin
      xyz="0.018 -0.264 0"
      rpy="-1.5708 0 3.1416" />
    <parent
      link="Arm_R4_Link" />
    <child
      link="Arm_R5_Link" />
    <axis
      xyz="0 0 1" />
    <limit
      lower="-3.0194"
      upper="3.0194"
      effort="5.5"
      velocity="3.1416" />
  </joint>
  <link
    name="Arm_R6_Link">
    <inertial>
      <origin
        xyz="-1.8634e-04 2.3824e-04 5.829e-04"
        rpy="0 0 0" />
      <mass
        value="0.3906229" />
      <inertia
        ixx="1.9943e-04"
        ixy="-1.1800e-06"
        ixz="-3.0000e-07"
        iyy="1.7163e-04"
        iyz="3.5300e-06"
        izz="1.8567e-04" />
    </inertial>
    <visual>
      <origin
        xyz="0 0 0"
        rpy="0 0 0" />
      <geometry>
        <mesh
          filename="package://marvin_description/meshes/Gento_Luna/Arm_R6_Link.STL" />
      </geometry>
      <material
        name="">
        <color
          rgba="1 0 0 1" />
      </material>
    </visual>
    <collision>
      <origin
        xyz="0 0 0"
        rpy="0 0 0" />
      <geometry>
        <mesh
          filename="package://marvin_description/meshes/Gento_Luna/Arm_R6_Link.STL" />
      </geometry>
    </collision>
  </link>
  <joint
    name="Arm_R6_Joint"
    type="revolute">
    <origin
      xyz="0 0 0"
      rpy="1.5708 -1.5708 0" />
    <parent
      link="Arm_R5_Link" />
    <child
      link="Arm_R6_Link" />
    <axis
      xyz="0 0 1" />
    <limit
      lower="-1.0472"
      upper="1.0472"
      effort="5.5"
      velocity="3.1416" />
  </joint>
  <link
    name="Arm_R7_Link">
    <inertial>
      <origin
        xyz="-5.2431e-04 -3.976234e-02 7.27342e-03"
        rpy="0 0 0" />
      <mass
        value="0.37939" />
      <inertia
        ixx="7.0308e-04"
        ixy="5.97e-06"
        ixz="7.30e-07"
        iyy="3.0365e-04"
        iyz="1.2769e-04"
        izz="5.8833e-04" />
    </inertial>
    <visual>
      <origin
        xyz="0 0 0"
        rpy="0 0 0" />
      <geometry>
        <mesh
          filename="package://marvin_description/meshes/Gento_Luna/Arm_R7_Link.STL" />
      </geometry>
      <material
        name="">
        <color
          rgba="0 1 0 1" />
      </material>
    </visual>
    <collision>
      <origin
        xyz="0 0 0"
        rpy="0 0 0" />
      <geometry>
        <mesh
          filename="package://marvin_description/meshes/Gento_Luna/Arm_R7_Link.STL" />
      </geometry>
    </collision>
  </link>
  <joint
    name="Arm_R7_Joint"
    type="revolute">
    <origin
      xyz="0 0 0"
      rpy="1.5708 -1.5708 0" />
    <parent
      link="Arm_R6_Link" />
    <child
      link="Arm_R7_Link" />
    <axis
      xyz="0 0 1" />
    <limit
      lower="-1.5708"
      upper="1.5708"
      effort="5.5"
      velocity="3.1416" />
  </joint>
  <link
    name="Arm_L1_Link">
    <inertial>
      <origin
        xyz="-3.3175e-04 -4.26687e-03 -3.522466e-02"
        rpy="0 0 0" />
      <mass
        value="1.537551" />
      <inertia
        ixx="3.66914e-03"
        ixy="1.77e-06"
        ixz="1.342e-05"
        iyy="3.94529e-03"
        iyz="-2.3437e-04"
        izz="1.31774e-03" />
    </inertial>
    <visual>
      <origin
        xyz="0 0 0"
        rpy="0 0 0" />
      <geometry>
        <mesh
          filename="package://marvin_description/meshes/Gento_Luna/Arm_L1_Link.STL" />
      </geometry>
      <material
        name="">
        <color
          rgba="0 1 0 1" />
      </material>
    </visual>
    <collision>
      <origin
        xyz="0 0 0"
        rpy="0 0 0" />
      <geometry>
        <mesh
          filename="package://marvin_description/meshes/Gento_Luna/Arm_L1_Link.STL" />
      </geometry>
    </collision>
  </link>
  <joint
    name="Arm_L1_Joint"
    type="revolute">
    <origin
      xyz="0 0.2146 0.3915"
      rpy="-1.5708 0 0" />
    <parent
      link="Leg_J6_Link" />
    <child
      link="Arm_L1_Link" />
    <axis
      xyz="0 0 1" />
    <limit
      lower="-3.0194"
      upper="3.0194"
      effort="35"
      velocity="3.1416" />
  </joint>
  <link
    name="Arm_L2_Link">
    <inertial>
      <origin
        xyz="-1.6285e-04 4.983697e-02 -8.33367e-03"
        rpy="0 0 0" />
      <mass
        value="1.540624" />
      <inertia
        ixx="5.98937e-03"
        ixy="1.663e-05"
        ixz="8.58e-06"
        iyy="1.83242e-03"
        iyz="6.4328e-04"
        izz="5.64358e-03" />
    </inertial>
    <visual>
      <origin
        xyz="0 0 0"
        rpy="0 0 0" />
      <geometry>
        <mesh
          filename="package://marvin_description/meshes/Gento_Luna/Arm_L2_Link.STL" />
      </geometry>
      <material
        name="">
        <color
          rgba="0 0 1 1" />
      </material>
    </visual>
    <collision>
      <origin
        xyz="0 0 0"
        rpy="0 0 0" />
      <geometry>
        <mesh
          filename="package://marvin_description/meshes/Gento_Luna/Arm_L2_Link.STL" />
      </geometry>
    </collision>
  </link>
  <joint
    name="Arm_L2_Joint"
    type="revolute">
    <origin
      xyz="0 0 0"
      rpy="-1.5708 0 3.1416" />
    <parent
      link="Arm_L1_Link" />
    <child
      link="Arm_L2_Link" />
    <axis
      xyz="0 0 1" />
    <limit
      lower="-2.0595"
      upper="2.0595"
      effort="35"
      velocity="3.1416" />
  </joint>
  <link
    name="Arm_L3_Link">
    <inertial>
      <origin
        xyz="8.2949e-03 -4.11162e-03 -4.916618e-02"
        rpy="0 0 0" />
      <mass
        value="1.361743" />
      <inertia
        ixx="4.67364e-03"
        ixy="-5.704e-05"
        ixz="5.8882e-04"
        iyy="4.98053e-03"
        iyz="-2.7207e-04"
        izz="1.19672e-03" />
    </inertial>
    <visual>
      <origin
        xyz="0 0 0"
        rpy="0 0 0" />
      <geometry>
        <mesh
          filename="package://marvin_description/meshes/Gento_Luna/Arm_L3_Link.STL" />
      </geometry>
      <material
        name="">
        <color
          rgba="1 0 0 1" />
      </material>
    </visual>
    <collision>
      <origin
        xyz="0 0 0"
        rpy="0 0 0" />
      <geometry>
        <mesh
          filename="package://marvin_description/meshes/Gento_Luna/Arm_L3_Link.STL" />
      </geometry>
    </collision>
  </link>
  <joint
    name="Arm_L3_Joint"
    type="revolute">
    <origin
      xyz="0 -0.264 0"
      rpy="-1.5708 0 -3.1416" />
    <parent
      link="Arm_L2_Link" />
    <child
      link="Arm_L3_Link" />
    <axis
      xyz="0 0 1" />
    <limit
      lower="-3.0194"
      upper="3.0194"
      effort="18"
      velocity="3.1416" />
  </joint>
  <link
    name="Arm_L4_Link">
    <inertial>
      <origin
        xyz="8.52387e-03 -3.857074e-02 -8.01541e-03"
        rpy="0 0 0" />
      <mass
        value="1.034295" />
      <inertia
        ixx="3.03957e-03"
        ixy="-3.7917e-04"
        ixz="6.787e-05"
        iyy="1.18553e-03"
        iyz="-3.1048e-04"
        izz="2.88173e-03" />
    </inertial>
    <visual>
      <origin
        xyz="0 0 0"
        rpy="0 0 0" />
      <geometry>
        <mesh
          filename="package://marvin_description/meshes/Gento_Luna/Arm_L4_Link.STL" />
      </geometry>
      <material
        name="">
        <color
          rgba="0 1 0 1" />
      </material>
    </visual>
    <collision>
      <origin
        xyz="0 0 0"
        rpy="0 0 0" />
      <geometry>
        <mesh
          filename="package://marvin_description/meshes/Gento_Luna/Arm_L4_Link.STL" />
      </geometry>
    </collision>
  </link>
  <joint
    name="Arm_L4_Joint"
    type="revolute">
    <origin
      xyz="0.018 0 0"
      rpy="-1.5708 0 3.1416" />
    <parent
      link="Arm_L3_Link" />
    <child
      link="Arm_L4_Link" />
    <axis
      xyz="0 0 1" />
    <limit
      lower="-2.5307"
      upper="0.7854"
      effort="18"
      velocity="3.1416" />
  </joint>
  <link
    name="Arm_L5_Link">
    <inertial>
      <origin
        xyz="-5.008e-04 2.23923e-03 -9.253416e-02"
        rpy="0 0 0" />
      <mass
        value="1.000479" />
      <inertia
        ixx="2.17057e-03"
        ixy="-1.142e-05"
        ixz="-6.68e-06"
        iyy="1.95131e-03"
        iyz="3.059e-05"
        izz="8.4222e-04" />
    </inertial>
    <visual>
      <origin
        xyz="0 0 0"
        rpy="0 0 0" />
      <geometry>
        <mesh
          filename="package://marvin_description/meshes/Gento_Luna/Arm_L5_Link.STL" />
      </geometry>
      <material
        name="">
        <color
          rgba="0 0 1 1" />
      </material>
    </visual>
    <collision>
      <origin
        xyz="0 0 0"
        rpy="0 0 0" />
      <geometry>
        <mesh
          filename="package://marvin_description/meshes/Gento_Luna/Arm_L5_Link.STL" />
      </geometry>
    </collision>
  </link>
  <joint
    name="Arm_L5_Joint"
    type="revolute">
    <origin
      xyz="0.018 -0.264 0"
      rpy="-1.5708 0 -3.1416" />
    <parent
      link="Arm_L4_Link" />
    <child
      link="Arm_L5_Link" />
    <axis
      xyz="0 0 1" />
    <limit
      lower="-3.0194"
      upper="3.0194"
      effort="5.5"
      velocity="3.1416" />
  </joint>
  <link
    name="Arm_L6_Link">
    <inertial>
      <origin
        xyz="1.8634e-04 2.3824e-04 -5.829e-04"
        rpy="0 0 0" />
      <mass
        value="0.3906229" />
      <inertia
        ixx="1.9943e-04"
        ixy="1.1800e-06"
        ixz="-3.0000e-07"
        iyy="1.7163e-04"
        iyz="-3.5300e-06"
        izz="1.8567e-04" />
    </inertial>
    <visual>
      <origin
        xyz="0 0 0"
        rpy="0 0 0" />
      <geometry>
        <mesh
          filename="package://marvin_description/meshes/Gento_Luna/Arm_L6_Link.STL" />
      </geometry>
      <material
        name="">
        <color
          rgba="1 0 0 1" />
      </material>
    </visual>
    <collision>
      <origin
        xyz="0 0 0"
        rpy="0 0 0" />
      <geometry>
        <mesh
          filename="package://marvin_description/meshes/Gento_Luna/Arm_L6_Link.STL" />
      </geometry>
    </collision>
  </link>
  <joint
    name="Arm_L6_Joint"
    type="revolute">
    <origin
      xyz="0 0 0"
      rpy="1.5708 -1.5708 0" />
    <parent
      link="Arm_L5_Link" />
    <child
      link="Arm_L6_Link" />
    <axis
      xyz="0 0 1" />
    <limit
      lower="-1.0472"
      upper="1.0472"
      effort="5.5"
      velocity="3.1416" />
  </joint>
  <link
    name="Arm_L7_Link">
    <inertial>
      <origin
        xyz="-5.2431e-04 -3.976234e-02 7.27342e-03"
        rpy="0 0 0" />
      <mass
        value="0.37939" />
      <inertia
        ixx="7.0308e-04"
        ixy="5.97e-06"
        ixz="7.30e-07"
        iyy="3.0365e-04"
        iyz="1.2769e-04"
        izz="5.8833e-04" />
    </inertial>
    <visual>
      <origin
        xyz="0 0 0"
        rpy="0 0 0" />
      <geometry>
        <mesh
          filename="package://marvin_description/meshes/Gento_Luna/Arm_L7_Link.STL" />
      </geometry>
      <material
        name="">
        <color
          rgba="0 1 0 1" />
      </material>
    </visual>
    <collision>
      <origin
        xyz="0 0 0"
        rpy="0 0 0" />
      <geometry>
        <mesh
          filename="package://marvin_description/meshes/Gento_Luna/Arm_L7_Link.STL" />
      </geometry>
    </collision>
  </link>
  <joint
    name="Arm_L7_Joint"
    type="revolute">
    <origin
      xyz="0 0 0"
      rpy="1.5708 -1.5708 0" />
    <parent
      link="Arm_L6_Link" />
    <child
      link="Arm_L7_Link" />
    <axis
      xyz="0 0 1" />
    <limit
      lower="-1.5708"
      upper="1.5708"
      effort="5.5"
      velocity="3.1416" />
  </joint>
  <link
    name="Head_J1_Link">
    <inertial>
      <origin
        xyz="9.4918E-07 0.017441 -0.0043026"
        rpy="0 0 0" />
      <mass
        value="0.7216" />
      <inertia
        ixx="0.0011491"
        ixy="-2.3245E-08"
        ixz="-1.802E-09"
        iyy="0.00077345"
        iyz="-5.6833E-05"
        izz="0.0011134" />
    </inertial>
    <visual>
      <origin
        xyz="0 0 0"
        rpy="0 0 0" />
      <geometry>
        <mesh
          filename="package://marvin_description/meshes/Gento_Luna/Head_J1_Link.STL" />
      </geometry>
      <material
        name="">
        <color
          rgba="0 1 0 1" />
      </material>
    </visual>
    <collision>
      <origin
        xyz="0 0 0"
        rpy="0 0 0" />
      <geometry>
        <mesh
          filename="package://marvin_description/meshes/Gento_Luna/Head_J1_Link.STL" />
      </geometry>
    </collision>
  </link>
  <joint
    name="Head_J1_joint"
    type="revolute">
    <origin
      xyz="-0.013496 0 0.49898"
      rpy="1.5708 0 0" />
    <parent
      link="Leg_J6_Link" />
    <child
      link="Head_J1_Link" />
    <axis
      xyz="0 0 1" />
    <limit
      lower="-0.523595776"
      upper="0.523595776"
      effort="18"
      velocity="3.665191429" />
  </joint>
  <link
    name="Head_J2_Link">
    <inertial>
      <origin
        xyz="0.052332 0.00010809 0.15733"
        rpy="0 0 0" />
      <mass
        value="2.3905" />
      <inertia
        ixx="0.0083456"
        ixy="-9.1023E-06"
        ixz="-0.0012055"
        iyy="0.010445"
        iyz="-3.2339E-06"
        izz="0.0071811" />
    </inertial>
    <visual>
      <origin
        xyz="0 0 0"
        rpy="0 0 0" />
      <geometry>
        <mesh
          filename="package://marvin_description/meshes/Gento_Luna/Head_J2_Link.STL" />
      </geometry>
      <material
        name="">
        <color
          rgba="0 0 1 1" />
      </material>
    </visual>
    <collision>
      <origin
        xyz="0 0 0"
        rpy="0 0 0" />
      <geometry>
        <mesh
          filename="package://marvin_description/meshes/Gento_Luna/Head_J2_Link.STL" />
      </geometry>
    </collision>
  </link>
  <joint
    name="Head_J2_Joint"
    type="revolute">
    <origin
      xyz="0 0 0"
      rpy="-1.5708 0 0" />
    <parent
      link="Head_J1_Link" />
    <child
      link="Head_J2_Link" />
    <axis
      xyz="0 0 1" />
    <limit
      lower="-1.570796327"
      upper="1.570796327"
      effort="18"
      velocity="3.665191429" />
  </joint>
</robot>
