<?xml version="1.0" ?>
<!-- =================================================================================== -->
<!-- |    This document was autogenerated by xacro from urdf/Marvin_Ultra.urdf.xacro   | -->
<!-- |    EDITING THIS FILE BY HAND IS NOT RECOMMENDED                                 | -->
<!-- =================================================================================== -->
<!-- This URDF was automatically created by SolidWorks to URDF Exporter! Originally created by Stephen Brawner (brawner@gmail.com) 
     Commit Version: 1.6.0-4-g7f85cfe  Build Version: 1.6.7995.38578
     For more information, please see http://wiki.ros.org/sw_urdf_exporter -->
<robot name="Marvin Ultra_URDF_2026.1.28">
  <link name="Base_L">
    <inertial>
      <origin rpy="0 0 0" xyz="0.00026267 0.00011932 0.03306285"/>
      <mass value="1.03862143"/>
      <inertia ixx="0.00071755" ixy="0.00000006" ixz="-0.00000688" iyy="0.00071148" iyz="-0.00000335" izz="0.00091518"/>
    </inertial>
    <visual>
      <origin rpy="0 0 0" xyz="0 0 0"/>
      <geometry>
        <mesh filename="package://marvin_description/meshes/m3/Base_L.STL"/>
      </geometry>
      <material name="">
        <color rgba="1 0 0 1"/>
      </material>
    </visual>
    <collision>
      <origin rpy="0 0 0" xyz="0 0 0"/>
      <geometry>
        <mesh filename="package://marvin_description/meshes/m3/Base_L.STL"/>
      </geometry>
    </collision>
  </link>
  <link name="Link1_L">
    <inertial>
      <origin rpy="0 0 0" xyz="0.00005324 0.00445236 -0.03913569"/>
      <mass value="1.77724008"/>
      <inertia ixx="0.00530846" ixy="0.00000240" ixz="-0.00000211" iyy="0.00555862" iyz="0.00029899" izz="0.00133520"/>
    </inertial>
    <visual>
      <origin rpy="0 0 0" xyz="0 0 0"/>
      <geometry>
        <mesh filename="package://marvin_description/meshes/m3/Link1_L.STL"/>
      </geometry>
      <material name="">
        <color rgba="0 1 0 1"/>
      </material>
    </visual>
    <collision>
      <origin rpy="0 0 0" xyz="0 0 0"/>
      <geometry>
        <mesh filename="package://marvin_description/meshes/m3/Link1_L.STL"/>
      </geometry>
    </collision>
  </link>
  <joint name="Joint1_L" type="revolute">
    <origin rpy="0 0 0" xyz="0 0 0.177"/>
    <parent link="Base_L"/>
    <child link="Link1_L"/>
    <axis xyz="0 0 1"/>
    <limit effort="66" lower="-3.1067" upper="3.1067" velocity="3.1416"/>
  </joint>
  <link name="Link2_L">
    <inertial>
      <origin rpy="0 0 0" xyz="-0.00010498 0.05321718 0.00787641"/>
      <mass value="1.60894018"/>
      <inertia ixx="0.00632572" ixy="-0.00000592" ixz="0.00000084" iyy="0.00182184" iyz="-0.00069610" izz="0.00594120"/>
    </inertial>
    <visual>
      <origin rpy="0 0 0" xyz="0 0 0"/>
      <geometry>
        <mesh filename="package://marvin_description/meshes/m3/Link2_L.STL"/>
      </geometry>
      <material name="">
        <color rgba="0 0 1 1"/>
      </material>
    </visual>
    <collision>
      <origin rpy="0 0 0" xyz="0 0 0"/>
      <geometry>
        <mesh filename="package://marvin_description/meshes/m3/Link2_L.STL"/>
      </geometry>
    </collision>
  </link>
  <joint name="Joint2_L" type="revolute">
    <origin rpy="1.5708 0 0" xyz="0 0 0"/>
    <parent link="Link1_L"/>
    <child link="Link2_L"/>
    <axis xyz="0 0 1"/>
    <limit effort="66" lower="-2.0944" upper="2.0944" velocity="3.1416"/>
  </joint>
  <link name="Link3_L">
    <inertial>
      <origin rpy="0 0 0" xyz="0.00810489 0.00245578 -0.05500367"/>
      <mass value="1.27082930"/>
      <inertia ixx="0.00491773" ixy="0.00003519" ixz="0.00058367" iyy="0.00519354" iyz="0.00017843" izz="0.00102662"/>
    </inertial>
    <visual>
      <origin rpy="0 0 0" xyz="0 0 0"/>
      <geometry>
        <mesh filename="package://marvin_description/meshes/m3/Link3_L.STL"/>
      </geometry>
      <material name="">
        <color rgba="1 0 0 1"/>
      </material>
    </visual>
    <collision>
      <origin rpy="0 0 0" xyz="0 0 0"/>
      <geometry>
        <mesh filename="package://marvin_description/meshes/m3/Link3_L.STL"/>
      </geometry>
    </collision>
  </link>
  <joint name="Joint3_L" type="revolute">
    <origin rpy="-1.5708 0 0" xyz="0 0.272 0"/>
    <parent link="Link2_L"/>
    <child link="Link3_L"/>
    <axis xyz="0 0 1"/>
    <limit effort="18" lower="-3.1067" upper="3.1067" velocity="3.1416"/>
  </joint>
  <link name="Link4_L">
    <inertial>
      <origin rpy="0 0 0" xyz="0.00709286 -0.03304509 0.00893402"/>
      <mass value="0.96124622"/>
      <inertia ixx="0.00254980" ixy="-0.00032269" ixz="-0.00006345" iyy="0.00107965" iyz="0.00029545" izz="0.00235605"/>
    </inertial>
    <visual>
      <origin rpy="0 0 0" xyz="0 0 0"/>
      <geometry>
        <mesh filename="package://marvin_description/meshes/m3/Link4_L.STL"/>
      </geometry>
      <material name="">
        <color rgba="0 1 0 1"/>
      </material>
    </visual>
    <collision>
      <origin rpy="0 0 0" xyz="0 0 0"/>
      <geometry>
        <mesh filename="package://marvin_description/meshes/m3/Link4_L.STL"/>
      </geometry>
    </collision>
  </link>
  <joint name="Joint4_L" type="revolute">
    <origin rpy="-1.5708 0 3.1416" xyz="0.018 0 0"/>
    <parent link="Link3_L"/>
    <child link="Link4_L"/>
    <axis xyz="0 0 1"/>
    <limit effort="18" lower="-3.1067" upper="3.1067" velocity="3.1416"/>
  </joint>
  <link name="Link5_L">
    <inertial>
      <origin rpy="0 0 0" xyz="-0.00062313 0.00098400 -0.09276174"/>
      <mass value="0.90217469"/>
      <inertia ixx="0.00189248" ixy="-0.00001906" ixz="-0.00002190" iyy="0.00174389" iyz="-0.00000835" izz="0.00075080"/>
    </inertial>
    <visual>
      <origin rpy="0 0 0" xyz="0 0 0"/>
      <geometry>
        <mesh filename="package://marvin_description/meshes/m3/Link5_L.STL"/>
      </geometry>
      <material name="">
        <color rgba="0 0 1 1"/>
      </material>
    </visual>
    <collision>
      <origin rpy="0 0 0" xyz="0 0 0"/>
      <geometry>
        <mesh filename="package://marvin_description/meshes/m3/Link5_L.STL"/>
      </geometry>
    </collision>
  </link>
  <joint name="Joint5_L" type="revolute">
    <origin rpy="-1.5708 0 3.1416" xyz="0.018 -0.256 0"/>
    <parent link="Link4_L"/>
    <child link="Link5_L"/>
    <axis xyz="0 0 1"/>
    <limit effort="6.5" lower="-3.1067" upper="3.1067" velocity="3.1416"/>
  </joint>
  <link name="Link6_L">
    <inertial>
      <origin rpy="0 0 0" xyz="0.00031369 0.00024238 -0.00041391"/>
      <mass value="0.33261055"/>
      <inertia ixx="0.00015388" ixy="0.00000140" ixz="-0.00000029" iyy="0.00015258" iyz="-0.00000262" izz="0.00013812"/>
    </inertial>
    <visual>
      <origin rpy="0 0 0" xyz="0 0 0"/>
      <geometry>
        <mesh filename="package://marvin_description/meshes/m3/Link6_L.STL"/>
      </geometry>
      <material name="">
        <color rgba="1 0 0 1"/>
      </material>
    </visual>
    <collision>
      <origin rpy="0 0 0" xyz="0 0 0"/>
      <geometry>
        <mesh filename="package://marvin_description/meshes/m3/Link6_L.STL"/>
      </geometry>
    </collision>
  </link>
  <joint name="Joint6_L" type="revolute">
    <origin rpy="1.5708 -1.5708 0" xyz="0 0 0"/>
    <parent link="Link5_L"/>
    <child link="Link6_L"/>
    <axis xyz="0 0 1"/>
    <limit effort="6.5" lower="-1.0472" upper="1.0472" velocity="3.1416"/>
  </joint>
  <link name="Link7_L">
    <inertial>
      <origin rpy="0 0 0" xyz="-0.00006959 -0.03969936 0.00413997"/>
      <mass value="0.30535389"/>
      <inertia ixx="0.00058153" ixy="-0.00000009" ixz="-0.00000084" iyy="0.00026536" iyz="0.00005594" izz="0.00048333"/>
    </inertial>
    <visual>
      <origin rpy="0 0 0" xyz="0 0 0"/>
      <geometry>
        <mesh filename="package://marvin_description/meshes/m3/Link7_L.STL"/>
      </geometry>
      <material name="">
        <color rgba="0 1 0 1"/>
      </material>
    </visual>
    <collision>
      <origin rpy="0 0 0" xyz="0 0 0"/>
      <geometry>
        <mesh filename="package://marvin_description/meshes/m3/Link7_L.STL"/>
      </geometry>
    </collision>
  </link>
  <joint name="Joint7_L" type="revolute">
    <origin rpy="1.5708 -1.5708 0" xyz="0 0 0"/>
    <parent link="Link6_L"/>
    <child link="Link7_L"/>
    <axis xyz="0 0 1"/>
    <limit effort="6.5" lower="-1.5708" upper="1.5708" velocity="3.1416"/>
  </joint>
  <link name="flange_L"/>
  <joint name="joint_flange_L" type="fixed">
    <origin rpy="1.5708 -1.5708 0" xyz="0.0 -0.088 0.0"/>
    <parent link="Link7_L"/>
    <child link="flange_L"/>
  </joint>
  <link name="Base_R">
    <inertial>
      <origin rpy="0 0 0" xyz="0.00026267 0.00011932 0.03306285"/>
      <mass value="1.03862143"/>
      <inertia ixx="0.00071755" ixy="0.00000006" ixz="-0.00000688" iyy="0.00071148" iyz="-0.00000335" izz="0.00091518"/>
    </inertial>
    <visual>
      <origin rpy="0 0 0" xyz="0 0 0"/>
      <geometry>
        <mesh filename="package://marvin_description/meshes/m3/Base_R.STL"/>
      </geometry>
      <material name="">
        <color rgba="1 0 0 1"/>
      </material>
    </visual>
    <collision>
      <origin rpy="0 0 0" xyz="0 0 0"/>
      <geometry>
        <mesh filename="package://marvin_description/meshes/m3/Base_R.STL"/>
      </geometry>
    </collision>
  </link>
  <link name="Link1_R">
    <inertial>
      <origin rpy="0 0 0" xyz="0.00005324 0.00445236 -0.03913569"/>
      <mass value="1.77724008"/>
      <inertia ixx="0.00530846" ixy="0.00000240" ixz="-0.00000211" iyy="0.00555862" iyz="0.00029899" izz="0.00133520"/>
    </inertial>
    <visual>
      <origin rpy="0 0 0" xyz="0 0 0"/>
      <geometry>
        <mesh filename="package://marvin_description/meshes/m3/Link1_R.STL"/>
      </geometry>
      <material name="">
        <color rgba="0 1 0 1"/>
      </material>
    </visual>
    <collision>
      <origin rpy="0 0 0" xyz="0 0 0"/>
      <geometry>
        <mesh filename="package://marvin_description/meshes/m3/Link1_R.STL"/>
      </geometry>
    </collision>
  </link>
  <joint name="Joint1_R" type="revolute">
    <origin rpy="0 0 0" xyz="0 0 0.177"/>
    <parent link="Base_R"/>
    <child link="Link1_R"/>
    <axis xyz="0 0 1"/>
    <limit effort="66" lower="-3.1067" upper="3.1067" velocity="3.1416"/>
  </joint>
  <link name="Link2_R">
    <inertial>
      <origin rpy="0 0 0" xyz="-0.00010498 0.05321718 0.00787641"/>
      <mass value="1.60894018"/>
      <inertia ixx="0.00632572" ixy="-0.00000592" ixz="0.00000084" iyy="0.00182184" iyz="-0.00069610" izz="0.00594120"/>
    </inertial>
    <visual>
      <origin rpy="0 0 0" xyz="0 0 0"/>
      <geometry>
        <mesh filename="package://marvin_description/meshes/m3/Link2_R.STL"/>
      </geometry>
      <material name="">
        <color rgba="0 0 1 1"/>
      </material>
    </visual>
    <collision>
      <origin rpy="0 0 0" xyz="0 0 0"/>
      <geometry>
        <mesh filename="package://marvin_description/meshes/m3/Link2_R.STL"/>
      </geometry>
    </collision>
  </link>
  <joint name="Joint2_R" type="revolute">
    <origin rpy="1.5708 0 0" xyz="0 0 0"/>
    <parent link="Link1_R"/>
    <child link="Link2_R"/>
    <axis xyz="0 0 1"/>
    <limit effort="66" lower="-2.0944" upper="2.0944" velocity="3.1416"/>
  </joint>
  <link name="Link3_R">
    <inertial>
      <origin rpy="0 0 0" xyz="0.00810489 0.00245578 -0.05500367"/>
      <mass value="1.27082930"/>
      <inertia ixx="0.00491773" ixy="0.00003519" ixz="0.00058367" iyy="0.00519354" iyz="0.00017843" izz="0.00102662"/>
    </inertial>
    <visual>
      <origin rpy="0 0 0" xyz="0 0 0"/>
      <geometry>
        <mesh filename="package://marvin_description/meshes/m3/Link3_R.STL"/>
      </geometry>
      <material name="">
        <color rgba="1 0 0 1"/>
      </material>
    </visual>
    <collision>
      <origin rpy="0 0 0" xyz="0 0 0"/>
      <geometry>
        <mesh filename="package://marvin_description/meshes/m3/Link3_R.STL"/>
      </geometry>
    </collision>
  </link>
  <joint name="Joint3_R" type="revolute">
    <origin rpy="-1.5708 0 0" xyz="0 0.272 0"/>
    <parent link="Link2_R"/>
    <child link="Link3_R"/>
    <axis xyz="0 0 1"/>
    <limit effort="18" lower="-3.1067" upper="3.1067" velocity="3.1416"/>
  </joint>
  <link name="Link4_R">
    <inertial>
      <origin rpy="0 0 0" xyz="0.00709286 -0.03304509 0.00893402"/>
      <mass value="0.96124622"/>
      <inertia ixx="0.00254980" ixy="-0.00032269" ixz="-0.00006345" iyy="0.00107965" iyz="0.00029545" izz="0.00235605"/>
    </inertial>
    <visual>
      <origin rpy="0 0 0" xyz="0 0 0"/>
      <geometry>
        <mesh filename="package://marvin_description/meshes/m3/Link4_R.STL"/>
      </geometry>
      <material name="">
        <color rgba="0 1 0 1"/>
      </material>
    </visual>
    <collision>
      <origin rpy="0 0 0" xyz="0 0 0"/>
      <geometry>
        <mesh filename="package://marvin_description/meshes/m3/Link4_R.STL"/>
      </geometry>
    </collision>
  </link>
  <joint name="Joint4_R" type="revolute">
    <origin rpy="-1.5708 0 3.1416" xyz="0.018 0 0"/>
    <parent link="Link3_R"/>
    <child link="Link4_R"/>
    <axis xyz="0 0 1"/>
    <limit effort="18" lower="-3.1067" upper="3.1067" velocity="3.1416"/>
  </joint>
  <link name="Link5_R">
    <inertial>
      <origin rpy="0 0 0" xyz="0.00062313 -0.00098400 -0.09276174"/>
      <mass value="0.90217469"/>
      <inertia ixx="0.00189248" ixy="-0.00001906" ixz="0.00002190" iyy="0.00174389" iyz="0.00000835" izz="0.00075080"/>
    </inertial>
    <visual>
      <origin rpy="0 0 0" xyz="0 0 0"/>
      <geometry>
        <mesh filename="package://marvin_description/meshes/m3/Link5_R.STL"/>
      </geometry>
      <material name="">
        <color rgba="0 0 1 1"/>
      </material>
    </visual>
    <collision>
      <origin rpy="0 0 0" xyz="0 0 0"/>
      <geometry>
        <mesh filename="package://marvin_description/meshes/m3/Link5_R.STL"/>
      </geometry>
    </collision>
  </link>
  <joint name="Joint5_R" type="revolute">
    <origin rpy="-1.5708 0 3.1416" xyz="0.018 -0.256 0"/>
    <parent link="Link4_R"/>
    <child link="Link5_R"/>
    <axis xyz="0 0 1"/>
    <limit effort="6.5" lower="-3.1067" upper="3.1067" velocity="3.1416"/>
  </joint>
  <link name="Link6_R">
    <inertial>
      <origin rpy="0 0 0" xyz="-0.00031369 0.00024238 0.00041391"/>
      <mass value="0.33261055"/>
      <inertia ixx="0.00015479" ixy="-0.00000140" ixz="-0.00000029" iyy="0.00015429" iyz="-0.00000262" izz="0.00013902"/>
    </inertial>
    <visual>
      <origin rpy="0 0 0" xyz="0 0 0"/>
      <geometry>
        <mesh filename="package://marvin_description/meshes/m3/Link6_R.STL"/>
      </geometry>
      <material name="">
        <color rgba="1 0 0 1"/>
      </material>
    </visual>
    <collision>
      <origin rpy="0 0 0" xyz="0 0 0"/>
      <geometry>
        <mesh filename="package://marvin_description/meshes/m3/Link6_R.STL"/>
      </geometry>
    </collision>
  </link>
  <joint name="Joint6_R" type="revolute">
    <origin rpy="1.5708 -1.5708 0" xyz="0 0 0"/>
    <parent link="Link5_R"/>
    <child link="Link6_R"/>
    <axis xyz="0 0 1"/>
    <limit effort="6.5" lower="-1.0472" upper="1.0472" velocity="3.1416"/>
  </joint>
  <link name="Link7_R">
    <inertial>
      <origin rpy="0 0 0" xyz="-0.00006959 -0.03969936 0.00413997"/>
      <mass value="0.30535389"/>
      <inertia ixx="0.00058153" ixy="-0.00000009" ixz="-0.00000084" iyy="0.00026536" iyz="0.00005594" izz="0.00048333"/>
    </inertial>
    <visual>
      <origin rpy="0 0 0" xyz="0 0 0"/>
      <geometry>
        <mesh filename="package://marvin_description/meshes/m3/Link7_R.STL"/>
      </geometry>
      <material name="">
        <color rgba="0 1 0 1"/>
      </material>
    </visual>
    <collision>
      <origin rpy="0 0 0" xyz="0 0 0"/>
      <geometry>
        <mesh filename="package://marvin_description/meshes/m3/Link7_R.STL"/>
      </geometry>
    </collision>
  </link>
  <joint name="Joint7_R" type="revolute">
    <origin rpy="1.5708 -1.5708 0" xyz="0 0 0"/>
    <parent link="Link6_R"/>
    <child link="Link7_R"/>
    <axis xyz="0 0 1"/>
    <limit effort="6.5" lower="-1.5708" upper="1.5708" velocity="3.1416"/>
  </joint>
  <link name="flange_R"/>
  <joint name="joint_flange_R" type="fixed">
    <origin rpy="1.5708 -1.5708 0" xyz="0.0 -0.088 0.0"/>
    <parent link="Link7_R"/>
    <child link="flange_R"/>
  </joint>
  <link name="base_link">
    <inertial>
      <origin rpy="0 0 0" xyz="0.15 -0.0 -0.08533949"/>
      <mass value="91.13"/>
      <inertia ixx="6.2017231" ixy="0.00119842" ixz="0.03392051" iyy="6.0077372" iyz="-1.3475249" izz="6.6799969"/>
    </inertial>
    <visual>
      <origin rpy="0 0 0" xyz="0 0 0"/>
      <geometry>
        <mesh filename="package://marvin_description/meshes/Marvin_Ultra/Underpan_Base_link.STL"/>
      </geometry>
      <material name="">
        <color rgba="1 0 0 1"/>
      </material>
    </visual>
    <collision>
      <origin rpy="0 0 0" xyz="0 0 0"/>
      <geometry>
        <mesh filename="package://marvin_description/meshes/Marvin_Ultra/Underpan_Base_link.STL"/>
      </geometry>
    </collision>
  </link>
  <link name="Leg_J1_Link">
    <inertial>
      <origin rpy="0 0 0" xyz="-0.01082075 0.00387295 -0.00593269"/>
      <mass value="5.518"/>
      <inertia ixx="0.02001314" ixy="-0.00092393" ixz="0.0009989" iyy="0.01789574" iyz="-0.00200503" izz="0.01413422"/>
    </inertial>
    <visual>
      <origin rpy="0 0 0" xyz="0 0 0"/>
      <geometry>
        <mesh filename="package://marvin_description/meshes/Marvin_Ultra/Leg_J1_Link.STL"/>
      </geometry>
      <material name="">
        <color rgba="0 1 0 1"/>
      </material>
    </visual>
    <collision>
      <origin rpy="0 0 0" xyz="0 0 0"/>
      <geometry>
        <mesh filename="package://marvin_description/meshes/Marvin_Ultra/Leg_J1_Link.STL"/>
      </geometry>
    </collision>
  </link>
  <joint name="Leg_J1_Joint" type="revolute">
    <origin rpy="1.5708 0 1.5708" xyz="0.093 0 0"/>
    <parent link="base_link"/>
    <child link="Leg_J1_Link"/>
    <axis xyz="0 0 1"/>
    <limit effort="204" lower="-0.5236" upper="0.5236" velocity="3.1416"/>
  </joint>
  <link name="Leg_J2_Link">
    <inertial>
      <origin rpy="0 0 0" xyz="-0.00089738 0.23016029 0.00790954"/>
      <mass value="7.3099823"/>
      <inertia ixx="0.51536571" ixy="-0.00701612" ixz="-0.0012673" iyy="0.0278392" iyz="0.02636815" izz="0.51521426"/>
    </inertial>
    <visual>
      <origin rpy="0 0 0" xyz="0 0 0"/>
      <geometry>
        <mesh filename="package://marvin_description/meshes/Marvin_Ultra/Leg_J2_Link.STL"/>
      </geometry>
      <material name="">
        <color rgba="0 0 1 1"/>
      </material>
    </visual>
    <collision>
      <origin rpy="0 0 0" xyz="0 0 0"/>
      <geometry>
        <mesh filename="package://marvin_description/meshes/Marvin_Ultra/Leg_J2_Link.STL"/>
      </geometry>
    </collision>
  </link>
  <joint name="Leg_J2_Joint" type="revolute">
    <origin rpy="0 -1.5708 0" xyz="0 0 0"/>
    <parent link="Leg_J1_Link"/>
    <child link="Leg_J2_Link"/>
    <axis xyz="0 0 1"/>
    <limit effort="204" lower="-1.4835" upper="0.5236" velocity="3.1416"/>
  </joint>
  <link name="Leg_J3_Link">
    <inertial>
      <origin rpy="0 0 0" xyz="0.00865229 0.13494754 -0.01500457"/>
      <mass value="3.4476637"/>
      <inertia ixx="0.13522209" ixy="0.00473931" ixz="-0.00001569" iyy="-0.00704875" iyz="-0.00704875" izz="0.12848576"/>
    </inertial>
    <visual>
      <origin rpy="0 0 0" xyz="0 0 0"/>
      <geometry>
        <mesh filename="package://marvin_description/meshes/Marvin_Ultra/Leg_J3_Link.STL"/>
      </geometry>
      <material name="">
        <color rgba="1 0 0 1"/>
      </material>
    </visual>
    <collision>
      <origin rpy="0 0 0" xyz="0 0 0"/>
      <geometry>
        <mesh filename="package://marvin_description/meshes/Marvin_Ultra/Leg_J3_Link.STL"/>
      </geometry>
    </collision>
  </link>
  <joint name="Leg_J3_Joint" type="revolute">
    <origin rpy="0 0 0" xyz="0 0.3 0"/>
    <parent link="Leg_J2_Link"/>
    <child link="Leg_J3_Link"/>
    <axis xyz="0 0 1"/>
    <limit effort="204" lower="0.0" upper="2.5307" velocity="3.1416"/>
  </joint>
  <link name="Leg_J4_Link">
    <inertial>
      <origin rpy="0 0 0" xyz="-0.0377824 0.00327962 0.01691895"/>
      <mass value="6.7521074"/>
      <inertia ixx="0.01633248" ixy="-0.00196807" ixz="-0.00148789" iyy="0.0474537" iyz="0.00113241" izz="0.04593688"/>
    </inertial>
    <visual>
      <origin rpy="0 0 0" xyz="0 0 0"/>
      <geometry>
        <mesh filename="package://marvin_description/meshes/Marvin_Ultra/Leg_J4_Link.STL"/>
      </geometry>
      <material name="">
        <color rgba="0 1 0 1"/>
      </material>
    </visual>
    <collision>
      <origin rpy="0 0 0" xyz="0 0 0"/>
      <geometry>
        <mesh filename="package://marvin_description/meshes/Marvin_Ultra/Leg_J4_Link.STL"/>
      </geometry>
    </collision>
  </link>
  <joint name="Leg_J4_Joint" type="revolute">
    <origin rpy="0 0 0" xyz="0 0.3 0"/>
    <parent link="Leg_J3_Link"/>
    <child link="Leg_J4_Link"/>
    <axis xyz="0 0 1"/>
    <limit effort="204" lower="-1.4835" upper="0.95993" velocity="3.1416"/>
  </joint>
  <link name="Leg_J5_Link">
    <inertial>
      <origin rpy="0 0 0" xyz="-0.00114217 0.13017545 -0.01115972"/>
      <mass value="3.9468269"/>
      <inertia ixx="0.1014756" ixy="-0.00070461" ixz="-0.00001716" iyy="0.02087895" iyz="-0.00168039" izz="0.08986108"/>
    </inertial>
    <visual>
      <origin rpy="0 0 0" xyz="0 0 0"/>
      <geometry>
        <mesh filename="package://marvin_description/meshes/Marvin_Ultra/Leg_J5_Link.STL"/>
      </geometry>
      <material name="">
        <color rgba="0 0 1 1"/>
      </material>
    </visual>
    <collision>
      <origin rpy="0 0 0" xyz="0 0 0"/>
      <geometry>
        <mesh filename="package://marvin_description/meshes/Marvin_Ultra/Leg_J5_Link.STL"/>
      </geometry>
    </collision>
  </link>
  <joint name="Leg_J5_Joint" type="revolute">
    <origin rpy="0 1.5708 0" xyz="0 0 0"/>
    <parent link="Leg_J4_Link"/>
    <child link="Leg_J5_Link"/>
    <axis xyz="0 0 1"/>
    <limit effort="54" lower="-0.523599" upper="0.523599" velocity="2.618"/>
  </joint>
  <link name="Leg_J6_Link">
    <inertial>
      <origin rpy="0 0 0" xyz="0.00093411 0.00177647 0.34965197"/>
      <mass value="9.5221899"/>
      <inertia ixx="1.2637405" ixy="0.00037429" ixz="0.00339082" iyy="1.2458381" iyz="0.00560089" izz="0.05627763"/>
    </inertial>
    <visual>
      <origin rpy="0 0 0" xyz="0 0 0"/>
      <geometry>
        <mesh filename="package://marvin_description/meshes/Marvin_Ultra/Leg_J6_Link.STL"/>
      </geometry>
      <material name="">
        <color rgba="1 0 0 1"/>
      </material>
    </visual>
    <collision>
      <origin rpy="0 0 0" xyz="0 0 0"/>
      <geometry>
        <mesh filename="package://marvin_description/meshes/Marvin_Ultra/Leg_J6_Link.STL"/>
      </geometry>
    </collision>
  </link>
  <joint name="Leg_J6_Joint" type="revolute">
    <origin rpy="-1.5708 -1.5708 0" xyz="0 0 0"/>
    <parent link="Leg_J5_Link"/>
    <child link="Leg_J6_Link"/>
    <axis xyz="0 0 1"/>
    <limit effort="54" lower="-2.5307" upper="2.5307" velocity="2.618"/>
  </joint>
  <link name="Head_J1_Link">
    <inertial>
      <origin rpy="0 0 0" xyz="-3.5275E-08 -0.0 0.0012515"/>
      <mass value="1.388"/>
      <inertia ixx="0.0023539" ixy="-1.0775E-09" ixz="-2.2637E-11" iyy="0.00023767" iyz="-6.2114E-05" izz="0.0023367"/>
    </inertial>
    <visual>
      <origin rpy="0 0 0" xyz="0 0 0"/>
      <geometry>
        <mesh filename="package://marvin_description/meshes/Marvin_Ultra/Head_J1_Link.STL"/>
      </geometry>
      <material name="">
        <color rgba="0 1 0 1"/>
      </material>
    </visual>
    <collision>
      <origin rpy="0 0 0" xyz="0 0 0"/>
      <geometry>
        <mesh filename="package://marvin_description/meshes/Marvin_Ultra/Head_J1_Link.STL"/>
      </geometry>
    </collision>
  </link>
  <joint name="Head_J1_Joint" type="revolute">
    <origin rpy="0 0 0" xyz="-0.0135 0 0.64"/>
    <parent link="Leg_J6_Link"/>
    <child link="Head_J1_Link"/>
    <axis xyz="0 0 1"/>
    <limit effort="18" lower="-1.5708" upper="1.5708" velocity="3.1416"/>
  </joint>
  <link name="Head_J2_Link">
    <inertial>
      <origin rpy="0 0 0" xyz="0.021932 0.039063 -0.00027743"/>
      <mass value="0.50512"/>
      <inertia ixx="0.0016475" ixy="4.9714E-05" ixz="-3.8607E-06" iyy="0.0010555" iyz="2.8944E-06" izz="0.0013656"/>
    </inertial>
    <visual>
      <origin rpy="0 0 0" xyz="0 0 0"/>
      <geometry>
        <mesh filename="package://marvin_description/meshes/Marvin_Ultra/Head_J2_Link.STL"/>
      </geometry>
      <material name="">
        <color rgba="0 0 1 1"/>
      </material>
    </visual>
    <collision>
      <origin rpy="0 0 0" xyz="0 0 0"/>
      <geometry>
        <mesh filename="package://marvin_description/meshes/Marvin_Ultra/Head_J2_Link.STL"/>
      </geometry>
    </collision>
  </link>
  <joint name="Head_J2_Joint" type="revolute">
    <origin rpy="1.5708 0 0" xyz="0 0 0"/>
    <parent link="Head_J1_Link"/>
    <child link="Head_J2_Link"/>
    <axis xyz="0 0 -1"/>
    <limit effort="18" lower="-0.4363" upper="0.61087" velocity="3.1416"/>
  </joint>
  <link name="eyes_link"/>
  <joint name="head_to_eyes_link" type="fixed">
    <parent link="Head_J2_Link"/>
    <child link="eyes_link"/>
    <origin rpy="-1.57 0 0" xyz="0.05 0.03 0"/>
  </joint>
  <link name="left_tool"/>
  <joint name="left_tool_joint" type="fixed">
    <parent link="flange_L"/>
    <child link="left_tool"/>
    <origin rpy="3.14 -1.57 0" xyz="0 0.00 .05"/>
  </joint>
  <link name="right_tool"/>
  <joint name="right_tool_joint" type="fixed">
    <parent link="flange_R"/>
    <child link="right_tool"/>
    <origin rpy="-3.14 -1.57 0" xyz="0 -0.00 .05"/>
  </joint>
  <joint name="ll6_to_left_arm" type="fixed">
    <parent link="Leg_J6_Link"/>
    <child link="Base_L"/>
    <origin rpy="-1.57 0 0" xyz="0 0.0585 0.423"/>
  </joint>
  <joint name="ll6_to_right_arm" type="fixed">
    <parent link="Leg_J6_Link"/>
    <child link="Base_R"/>
    <origin rpy="1.57 0 0" xyz="0 -0.0585 0.423"/>
  </joint>
  <link name="base_link"/>
  <joint name="base_to_base_link" type="fixed">
    <parent link="base_link"/>
    <child link="base_link"/>
    <origin rpy="0 0 0" xyz="0 0 0"/>
  </joint>
  <link name="tracking_base_link"/>
  <joint name="base_to_tracking_base_link" type="fixed">
    <parent link="tracking_base_link"/>
    <child link="base_link"/>
    <origin rpy="0 0 0" xyz="0 0 0.335"/>
  </joint>
  <link name="torso_link"/>
  <joint name="ll6_to_torso_link" type="fixed">
    <parent link="Leg_J6_Link"/>
    <child link="torso_link"/>
    <origin rpy="0 0 0" xyz="0 0 0.3"/>
  </joint>
</robot>
