<?xml version='1.0' encoding='UTF-8'?>
<mujoco model="Marvin Max_2026.4.03">
  <compiler angle="radian"/>
  <asset>
    <mesh name="Base_L" content_type="model/stl" file="../../meshes/m6/Base_L.STL"/>
    <mesh name="Link1_L" content_type="model/stl" file="../../meshes/m6/Link1_L.STL"/>
    <mesh name="Link2_L" content_type="model/stl" file="../../meshes/m6/Link2_L.STL"/>
    <mesh name="Link3_L" content_type="model/stl" file="../../meshes/m6/Link3_L.STL"/>
    <mesh name="Link4_L" content_type="model/stl" file="../../meshes/m6/Link4_L.STL"/>
    <mesh name="Link5_L" content_type="model/stl" file="../../meshes/m6/Link5_L.STL"/>
    <mesh name="Link6_L" content_type="model/stl" file="../../meshes/m6/Link6_L.STL"/>
    <mesh name="Link7_L" content_type="model/stl" file="../../meshes/m6/Link7_L.STL"/>
    <mesh name="Base_R" content_type="model/stl" file="../../meshes/m6/Base_R.STL"/>
    <mesh name="Link1_R" content_type="model/stl" file="../../meshes/m6/Link1_R.STL"/>
    <mesh name="Link2_R" content_type="model/stl" file="../../meshes/m6/Link2_R.STL"/>
    <mesh name="Link3_R" content_type="model/stl" file="../../meshes/m6/Link3_R.STL"/>
    <mesh name="Link4_R" content_type="model/stl" file="../../meshes/m6/Link4_R.STL"/>
    <mesh name="Link5_R" content_type="model/stl" file="../../meshes/m6/Link5_R.STL"/>
    <mesh name="Link6_R" content_type="model/stl" file="../../meshes/m6/Link6_R.STL"/>
    <mesh name="Link7_R" content_type="model/stl" file="../../meshes/m6/Link7_R.STL"/>
    <mesh name="base_link" content_type="model/stl" file="../../meshes/Gento_Sky/Underpan_Base_link.STL"/>
    <mesh name="left_front wheel_Link_1" content_type="model/stl" file="../../meshes/Gento_Sky/left_front_wheel_Link_1.STL"/>
    <mesh name="left_front wheel_Link_2" content_type="model/stl" file="../../meshes/Gento_Sky/left_front_wheel_Link_2.STL"/>
    <mesh name="right_front wheel_Link_1" content_type="model/stl" file="../../meshes/Gento_Sky/right_front_wheel_Link_1.STL"/>
    <mesh name="right_front wheel_Link_2" content_type="model/stl" file="../../meshes/Gento_Sky/right_front_wheel_Link_2.STL"/>
    <mesh name="left_back wheel_Link_1" content_type="model/stl" file="../../meshes/Gento_Sky/left_back_wheel_Link_1.STL"/>
    <mesh name="left_back wheel_Link_2" content_type="model/stl" file="../../meshes/Gento_Sky/left_back_wheel_Link_2.STL"/>
    <mesh name="right_back wheel_Link_1" content_type="model/stl" file="../../meshes/Gento_Sky/right_back_wheel_Link_1.STL"/>
    <mesh name="right_back wheel_Link_2" content_type="model/stl" file="../../meshes/Gento_Sky/right_back_wheel_Link_2.STL"/>
    <mesh name="waist_Link_1_prismatic" content_type="model/stl" file="../../meshes/Gento_Sky/waist_Link_1_prismatic.STL"/>
    <mesh name="waist_Link_2" content_type="model/stl" file="../../meshes/Gento_Sky/waist_Link_2.STL"/>
    <mesh name="waist_Link_3" content_type="model/stl" file="../../meshes/Gento_Sky/waist_Link_3.STL"/>
    <mesh name="head_Link_1" content_type="model/stl" file="../../meshes/Gento_Sky/head_Link_1.STL"/>
    <mesh name="head_Link_2" content_type="model/stl" file="../../meshes/Gento_Sky/head_Link_2.STL"/>
  </asset>
  <worldbody>
    <body name="base_link">
      <inertial pos="-0.05101 -4.4993e-05 0.46366" quat="0.70986 0.0259471 0.0258146 0.703391" mass="140.56" diaginertia="13.477 12.9392 2.24517"/>
      <geom type="mesh" rgba="0.59216 0.61961 0.65098 1" mesh="base_link"/>
      <body name="left_front wheel_Link_1" pos="0.23 0.218 0.07">
        <inertial pos="4.7248e-05 -0.024805 0.07456" quat="0.664121 -0.250193 0.248778 0.659134" mass="0.62536" diaginertia="0.000765988 0.000736999 0.000303154"/>
        <geom type="mesh" rgba="0.89804 0.91765 0.92941 1" mesh="left_front wheel_Link_1"/>
        <body name="left_front wheel_Link_2" quat="0.707105 -0.707108 0 0">
          <inertial pos="-2.452e-06 -1.127e-05 0.00050827" quat="-0.0149249 0.706966 0.0148707 0.706934" mass="1.2504" diaginertia="0.0038354 0.0020939 0.0020936"/>
          <geom type="mesh" rgba="0.8902 0.8902 0.91373 1" mesh="left_front wheel_Link_2"/>
        </body>
      </body>
      <body name="right_front wheel_Link_1" pos="0.23 -0.218 0.07">
        <inertial pos="-4.7248e-05 0.024805 0.07456" quat="0.664121 0.250193 -0.248778 0.659134" mass="0.62536" diaginertia="0.000765988 0.000736999 0.000303154"/>
        <geom type="mesh" rgba="0.89804 0.91765 0.92941 1" mesh="right_front wheel_Link_1"/>
        <body name="right_front wheel_Link_2" quat="0.707105 -0.707108 0 0">
          <inertial pos="2.452e-06 -1.127e-05 -0.00050827" quat="0.0149249 0.706966 -0.0148707 0.706934" mass="1.2504" diaginertia="0.0038354 0.0020939 0.0020936"/>
          <geom type="mesh" rgba="0.8902 0.8902 0.91373 1" mesh="right_front wheel_Link_2"/>
        </body>
      </body>
      <body name="left_back wheel_Link_1" pos="-0.23 0.218 0.07">
        <inertial pos="4.72481e-05 -0.0248051 0.0745597" quat="0.664121 -0.250193 0.248779 0.659133" mass="0.625359" diaginertia="0.000765984 0.000736999 0.000303155"/>
        <geom type="mesh" rgba="0.898039 0.917647 0.929412 1" mesh="left_back wheel_Link_1"/>
        <body name="left_back wheel_Link_2" quat="0.707105 -0.707108 0 0">
          <inertial pos="-2.452e-06 -1.12698e-05 0.00050827" quat="-0.0196098 0.706851 0.0195554 0.70682" mass="1.25042" diaginertia="0.00383545 0.00209388 0.00209365"/>
          <geom type="mesh" rgba="0.890196 0.890196 0.913725 1" mesh="left_back wheel_Link_2"/>
        </body>
      </body>
      <body name="right_back wheel_Link_1" pos="-0.23 -0.218 0.07">
        <inertial pos="-4.72479e-05 0.0248051 0.0745597" quat="0.664121 0.250193 -0.248779 0.659133" mass="0.625359" diaginertia="0.000765984 0.000736999 0.000303155"/>
        <geom type="mesh" rgba="0.898039 0.917647 0.929412 1" mesh="right_back wheel_Link_1"/>
        <body name="right_back wheel_Link_2" quat="0.707105 -0.707108 0 0">
          <inertial pos="2.452e-06 -1.12698e-05 -0.00050827" quat="0.0196098 0.706851 -0.0195554 0.70682" mass="1.25042" diaginertia="0.00383545 0.00209388 0.00209365"/>
          <geom type="mesh" rgba="0.890196 0.890196 0.913725 1" mesh="right_back wheel_Link_2"/>
        </body>
      </body>
      <body name="waist_Link_1_prismatic" pos="0.18048 0 0.36213">
        <inertial pos="-0.0430437 -0.00099041 -0.00314067" quat="0.517936 0.48614 0.481178 0.513691" mass="6.05415" diaginertia="0.0418492 0.0367347 0.0137884"/>
        <joint name="waist_joint_1" pos="0 0 0" axis="0 0 1" type="slide" range="0 0.86"/>
        <geom type="mesh" rgba="0.592157 0.619608 0.65098 1" mesh="waist_Link_1_prismatic"/>
        <body name="waist_Link_2" quat="0.707105 0.707108 0 0">
          <inertial pos="0.0026398 0.022352 -0.0012175" quat="0.523517 0.469801 -0.572878 0.420748" mass="5.3546" diaginertia="0.0200753 0.019053 0.0177587"/>
          <joint name="waist_joint_2" pos="0 0 0" axis="0 0 1" range="-1.5708 0" actuatorfrcrange="-194 194"/>
          <geom type="mesh" rgba="0.59216 0.61961 0.65098 1" mesh="waist_Link_2"/>
          <body name="waist_Link_3" quat="0.707105 -0.707108 0 0">
            <inertial pos="0.0044004 9.6396e-05 0.34103" quat="0.716711 0.0357452 0.0364315 0.6955" mass="16.415" diaginertia="0.244611 0.243801 0.0983847"/>
            <joint name="waist_joint_3" pos="0 0 0" axis="0 0 1" range="-0.4363 0.4363" actuatorfrcrange="-194 194"/>
            <geom type="mesh" rgba="0.59216 0.61961 0.65098 1" mesh="waist_Link_3"/>
            <body name="head_Link_1" pos="-0.0135 0 0.648">
              <inertial pos="-0.0003618 -0.012521 -0.017538" quat="0.995069 0.0912978 0.0176264 -0.0345199" mass="1.3932" diaginertia="0.00329882 0.00326379 0.00156189"/>
              <joint name="Head_J1_Joint" pos="0 0 0" axis="0 0 1" range="-1.5708 1.5708" actuatorfrcrange="-22 22"/>
              <geom type="mesh" rgba="0.59216 0.61961 0.65098 1" mesh="head_Link_1"/>
              <body name="head_Link_2" quat="0.707105 0.707108 0 0">
                <inertial pos="0.056578 0.029149 -0.018877" quat="0.498453 0.823312 0.0794911 -0.259583" mass="1.0575" diaginertia="0.00445223 0.00375093 0.00252014"/>
                <joint name="Head_J2_Joint" pos="0 0 0" axis="0 0 -1" range="-0.2 0.4363" actuatorfrcrange="-22 22"/>
                <geom type="mesh" rgba="0.59216 0.61961 0.65098 1" mesh="head_Link_2"/>
              </body>
            </body>
            <body name="Base_L" pos="0 0.056 0.4335" quat="0.707105 -0.707108 0 0">
              <inertial pos="0.00032267 4.798e-05 0.0406635" quat="0.582787 0.36644 -0.620273 0.375956" mass="1.1962" diaginertia="0.00127375 0.00107367 0.00106904"/>
              <geom type="mesh" rgba="0.792157 0.819608 0.933333 1" mesh="Base_L"/>
              <body name="Link1_L" pos="0 0 0.1745">
                <inertial pos="2.347e-05 0.0055715 -0.03076" quat="0.711599 0.0343691 -0.0341702 0.700912" mass="1.9705" diaginertia="0.00529754 0.00492285 0.00184874"/>
                <joint name="Joint1_L" pos="0 0 0" axis="0 0 1" range="-3.1067 3.1067" actuatorfrcrange="-108 108"/>
                <geom type="mesh" rgba="0.792157 0.819608 0.933333 1" mesh="Link1_L"/>
                <body name="Link2_L" quat="0.707105 0.707108 0 0">
                  <inertial pos="0.00013483 0.0617046 0.00950639" quat="0.643375 0.765551 -3.57328e-05 0.000294349" mass="2.24398" diaginertia="0.0119493 0.0112156 0.00338374"/>
                  <joint name="Joint2_L" pos="0 0 0" axis="0 0 1" range="-2.0944 2.0944" actuatorfrcrange="-108 108"/>
                  <geom type="mesh" rgba="0.792157 0.819608 0.933333 1" mesh="Link2_L"/>
                  <body name="Link3_L" pos="0 0.287 0" quat="0.707105 -0.707108 0 0">
                    <inertial pos="0.00968562 0.00246599 -0.046273" quat="0.782446 -0.0355285 -0.0735516 0.617337" mass="1.9242" diaginertia="0.00765215 0.00730789 0.0016338"/>
                    <joint name="Joint3_L" pos="0 0 0" axis="0 0 1" range="-3.1067 3.1067" actuatorfrcrange="-66 66"/>
                    <geom type="mesh" rgba="0.792157 0.819608 0.933333 1" mesh="Link3_L"/>
                    <body name="Link4_L" pos="0.018 0 0" quat="-2.59734e-06 2.59735e-06 -0.707108 0.707105">
                      <inertial pos="0.00850411 -0.0471822 0.00941509" quat="0.741754 0.628694 0.0774999 -0.220317" mass="1.6085" diaginertia="0.00603244 0.00535875 0.00198228"/>
                      <joint name="Joint4_L" pos="0 0 0" axis="0 0 1" range="-2.5307 1.0472" actuatorfrcrange="-66 66"/>
                      <geom type="mesh" rgba="0.792157 0.819608 0.933333 1" mesh="Link4_L"/>
                      <body name="Link5_L" pos="0.018 -0.314 0" quat="-2.59734e-06 2.59735e-06 -0.707108 0.707105">
                        <inertial pos="0.00051127 0.00101064 -0.112717" quat="0.999438 -0.00995046 -0.00675781 0.0312997" mass="2.0883" diaginertia="0.00626924 0.00564262 0.00243436"/>
                        <joint name="Joint5_L" pos="0 0 0" axis="0 0 1" range="-3.1067 3.1067" actuatorfrcrange="-18 18"/>
                        <geom type="mesh" rgba="0.792157 0.819608 0.933333 1" mesh="Link5_L"/>
                        <body name="Link6_L" quat="0.499998 0.5 -0.5 0.500002">
                          <inertial pos="0.00032659 0.00531336 -0.00030182" quat="0.718188 -0.0225408 0.00407878 0.695472" mass="0.72496" diaginertia="0.000517351 0.000460362 0.000425057"/>
                          <joint name="Joint6_L" pos="0 0 0" axis="0 0 1" range="-1.0472 1.0472" actuatorfrcrange="-18 18"/>
                          <geom type="mesh" rgba="0.792157 0.819608 0.933333 1" mesh="Link6_L"/>
                          <body name="Link7_L" quat="0.499998 0.5 -0.5 0.500002">
                            <inertial pos="-9.108e-05 -0.0315325 0.00889371" quat="0.84481 0.535026 0.00229584 -0.00609725" mass="0.68606" diaginertia="0.00173691 0.00153911 0.000745263"/>
                            <joint name="Joint7_L" pos="0 0 0" axis="0 0 1" range="-1.5708 1.5708" actuatorfrcrange="-18 18"/>
                            <geom type="mesh" rgba="0.792157 0.819608 0.933333 1" mesh="Link7_L"/>
                            <body name="flange_L" pos="0 -0.088 0" quat="0.499998 0.5 -0.5 0.500002"/>
                          </body>
                        </body>
                      </body>
                    </body>
                  </body>
                </body>
              </body>
            </body>
            <body name="Base_R" pos="0 -0.056 0.4335" quat="0.707105 0.707108 0 0">
              <inertial pos="0.00032267 4.798e-05 0.0406635" quat="0.582787 0.36644 -0.620273 0.375956" mass="1.1962" diaginertia="0.00127375 0.00107367 0.00106904"/>
              <geom type="mesh" rgba="0.792157 0.819608 0.933333 1" mesh="Base_R"/>
              <body name="Link1_R" pos="0 0 0.1745">
                <inertial pos="2.347e-05 0.0055715 -0.03076" quat="0.711599 0.0343691 -0.0341702 0.700912" mass="1.9705" diaginertia="0.00529754 0.00492285 0.00184874"/>
                <joint name="Joint1_R" pos="0 0 0" axis="0 0 1" range="-3.1067 3.1067" actuatorfrcrange="-108 108"/>
                <geom type="mesh" rgba="0.792157 0.819608 0.933333 1" mesh="Link1_R"/>
                <body name="Link2_R" quat="0.707105 0.707108 0 0">
                  <inertial pos="0.00013483 0.0617046 0.00950639" quat="0.643375 0.765551 -3.57328e-05 0.000294349" mass="2.24398" diaginertia="0.0119493 0.0112156 0.00338374"/>
                  <joint name="Joint2_R" pos="0 0 0" axis="0 0 1" range="-2.0944 2.0944" actuatorfrcrange="-108 108"/>
                  <geom type="mesh" rgba="0.792157 0.819608 0.933333 1" mesh="Link2_R"/>
                  <body name="Link3_R" pos="0 0.287 0" quat="0.707105 -0.707108 0 0">
                    <inertial pos="0.00968562 0.00246599 -0.046273" quat="0.782446 -0.0355285 -0.0735516 0.617337" mass="1.9242" diaginertia="0.00765215 0.00730789 0.0016338"/>
                    <joint name="Joint3_R" pos="0 0 0" axis="0 0 1" range="-3.1067 3.1067" actuatorfrcrange="-66 66"/>
                    <geom type="mesh" rgba="0.792157 0.819608 0.933333 1" mesh="Link3_R"/>
                    <body name="Link4_R" pos="0.018 0 0" quat="-2.59734e-06 2.59735e-06 -0.707108 0.707105">
                      <inertial pos="0.00850411 -0.0471822 0.00941509" quat="0.741754 0.628694 0.0774999 -0.220317" mass="1.6085" diaginertia="0.00603244 0.00535875 0.00198228"/>
                      <joint name="Joint4_R" pos="0 0 0" axis="0 0 1" range="-2.5307 1.0472" actuatorfrcrange="-66 66"/>
                      <geom type="mesh" rgba="0.792157 0.819608 0.933333 1" mesh="Link4_R"/>
                      <body name="Link5_R" pos="0.018 -0.314 0" quat="-2.59734e-06 2.59735e-06 -0.707108 0.707105">
                        <inertial pos="-0.00051127 -0.00101064 -0.112717" quat="0.999438 0.00995046 0.00675781 0.0312997" mass="2.0883" diaginertia="0.00626924 0.00564262 0.00243436"/>
                        <joint name="Joint5_R" pos="0 0 0" axis="0 0 1" range="-3.1067 3.1067" actuatorfrcrange="-18 18"/>
                        <geom type="mesh" rgba="0.792157 0.819608 0.933333 1" mesh="Link5_R"/>
                        <body name="Link6_R" quat="0.499998 0.5 -0.5 0.500002">
                          <inertial pos="0.00032659 -0.00531336 0.00030182" quat="0.695472 -0.00407878 0.0225408 0.718188" mass="0.72496" diaginertia="0.000517351 0.000460362 0.000425057"/>
                          <joint name="Joint6_R" pos="0 0 0" axis="0 0 1" range="-1.0472 1.0472" actuatorfrcrange="-18 18"/>
                          <geom type="mesh" rgba="0.792157 0.819608 0.933333 1" mesh="Link6_R"/>
                          <body name="Link7_R" quat="0.499998 0.5 -0.5 0.500002">
                            <inertial pos="-9.108e-05 -0.0315325 0.00889371" quat="0.84481 0.535026 0.00229584 -0.00609725" mass="0.68606" diaginertia="0.00173691 0.00153911 0.000745263"/>
                            <joint name="Joint7_R" pos="0 0 0" axis="0 0 1" range="-1.5708 1.5708" actuatorfrcrange="-18 18"/>
                            <geom type="mesh" rgba="0.792157 0.819608 0.933333 1" mesh="Link7_R"/>
                            <body name="flange_R" pos="0 -0.088 0" quat="0.499998 0.5 -0.5 0.500002"/>
                          </body>
                        </body>
                      </body>
                    </body>
                  </body>
                </body>
              </body>
            </body>
          </body>
        </body>
      </body>
    </body>
  </worldbody>
</mujoco>
