<?xml version="1.0" ?>
<!-- =================================================================================== -->
<!-- |    This document was autogenerated by xacro from urdf/Marvin_Max.urdf.xacro     | -->
<!-- |    EDITING THIS FILE BY HAND IS NOT RECOMMENDED                                 | -->
<!-- =================================================================================== -->
<!-- This URDF was automatically created by SolidWorks to URDF Exporter! Originally created by Stephen Brawner (brawner@gmail.com) 
     Commit Version: 1.6.0-4-g7f85cfe  Build Version: 1.6.7995.38578
     For more information, please see http://wiki.ros.org/sw_urdf_exporter -->
<robot name="Marvin Max_2026.4.03">
  <link name="Base_L">
    <inertial>
      <origin rpy="0 0 0" xyz="0.00032267 4.798E-05 0.04066353"/>
      <mass value="1.1962"/>
      <inertia ixx="0.00107329" ixy="-1.68E-06" ixz="-1.05E-05" iyy="0.00107003" iyz="-3.43E-06" izz="0.00127315"/>
    </inertial>
    <visual>
      <origin rpy="0 0 0" xyz="0 0 0"/>
      <geometry>
        <mesh filename="../meshes/m6/Base_L.STL"/>
      </geometry>
      <material name="">
        <color rgba="0.792156862745098 0.819607843137255 0.933333333333333 1"/>
      </material>
    </visual>
    <collision>
      <origin rpy="0 0 0" xyz="0 0 0"/>
      <geometry>
        <mesh filename="../meshes/m6/Base_L.STL"/>
      </geometry>
    </collision>
  </link>
  <link name="Link1_L">
    <inertial>
      <origin rpy="0 0 0" xyz="0.00002347 0.00557150 -0.03075998"/>
      <mass value="1.9705"/>
      <inertia ixx="0.00492293" ixy="0.00000550" ixz="0.00000193" iyy="0.00526513" iyz="0.00033232" izz="0.00188107"/>
    </inertial>
    <visual>
      <origin rpy="0 0 0" xyz="0 0 0"/>
      <geometry>
        <mesh filename="../meshes/m6/Link1_L.STL"/>
      </geometry>
      <material name="">
        <color rgba="0.792156862745098 0.819607843137255 0.933333333333333 1"/>
      </material>
    </visual>
    <collision>
      <origin rpy="0 0 0" xyz="0 0 0"/>
      <geometry>
        <mesh filename="../meshes/m6/Link1_L.STL"/>
      </geometry>
    </collision>
  </link>
  <joint name="Joint1_L" type="revolute">
    <origin rpy="0 0 0" xyz="0 0 0.1745"/>
    <parent link="Base_L"/>
    <child link="Link1_L"/>
    <axis xyz="0 0 1"/>
    <limit effort="108" lower="-3.1067" upper="3.1067" velocity="3.1416"/>
  </joint>
  <link name="Link2_L">
    <inertial>
      <origin rpy="0 0 0" xyz="0.00013483 0.06170460 0.00950639"/>
      <mass value="2.24398"/>
      <inertia ixx="0.01194933" ixy="0.00000336" ixz="0.00000091" iyy="0.00361581" iyz="-0.00132804" izz="0.01098356"/>
    </inertial>
    <visual>
      <origin rpy="0 0 0" xyz="0 0 0"/>
      <geometry>
        <mesh filename="../meshes/m6/Link2_L.STL"/>
      </geometry>
      <material name="">
        <color rgba="0.792156862745098 0.819607843137255 0.933333333333333 1"/>
      </material>
    </visual>
    <collision>
      <origin rpy="0 0 0" xyz="0 0 0"/>
      <geometry>
        <mesh filename="../meshes/m6/Link2_L.STL"/>
      </geometry>
    </collision>
  </link>
  <joint name="Joint2_L" type="revolute">
    <origin rpy="1.5708 0 0" xyz="0 0 0"/>
    <parent link="Link1_L"/>
    <child link="Link2_L"/>
    <axis xyz="0 0 1"/>
    <limit effort="108" lower="-2.0944" upper="2.0944" velocity="3.1416"/>
  </joint>
  <link name="Link3_L">
    <inertial>
      <origin rpy="0 0 0" xyz="0.00968562 0.00246599 -0.04627302"/>
      <mass value="1.9242"/>
      <inertia ixx="0.00718224" ixy="0.00004413" ixz="0.00089552" iyy="0.00762563" iyz="0.00022096" izz="0.00178597"/>
    </inertial>
    <visual>
      <origin rpy="0 0 0" xyz="0 0 0"/>
      <geometry>
        <mesh filename="../meshes/m6/Link3_L.STL"/>
      </geometry>
      <material name="">
        <color rgba="0.792156862745098 0.819607843137255 0.933333333333333 1"/>
      </material>
    </visual>
    <collision>
      <origin rpy="0 0 0" xyz="0 0 0"/>
      <geometry>
        <mesh filename="../meshes/m6/Link3_L.STL"/>
      </geometry>
    </collision>
  </link>
  <joint name="Joint3_L" type="revolute">
    <origin rpy="-1.5708 0 0" xyz="0 0.287 0"/>
    <parent link="Link2_L"/>
    <child link="Link3_L"/>
    <axis xyz="0 0 1"/>
    <limit effort="66" lower="-3.1067" upper="3.1067" velocity="3.1416"/>
  </joint>
  <link name="Link4_L">
    <inertial>
      <origin rpy="0 0 0" xyz="0.00850411 -0.04718223 0.00941509"/>
      <mass value="1.6085"/>
      <inertia ixx="0.00580480" ixy="-0.00066669" ixz="-0.00012722" iyy="0.00223807" iyz="0.00070523" izz="0.00533060"/>
    </inertial>
    <visual>
      <origin rpy="0 0 0" xyz="0 0 0"/>
      <geometry>
        <mesh filename="../meshes/m6/Link4_L.STL"/>
      </geometry>
      <material name="">
        <color rgba="0.792156862745098 0.819607843137255 0.933333333333333 1"/>
      </material>
    </visual>
    <collision>
      <origin rpy="0 0 0" xyz="0 0 0"/>
      <geometry>
        <mesh filename="../meshes/m6/Link4_L.STL"/>
      </geometry>
    </collision>
  </link>
  <joint name="Joint4_L" type="revolute">
    <origin rpy="-1.5708 0 3.1416" xyz="0.018 0 0"/>
    <parent link="Link3_L"/>
    <child link="Link4_L"/>
    <axis xyz="0 0 1"/>
    <limit effort="66" lower="-2.5307" upper="1.0472" velocity="3.1416"/>
  </joint>
  <link name="Link5_L">
    <inertial>
      <origin rpy="0 0 0" xyz="0.00051127 0.00101064 -0.11271739"/>
      <mass value="2.0883"/>
      <inertia ixx="0.00626603" ixy="0.00004009" ixz="0.00005338" iyy="0.00564387" iyz="-0.00006193" izz="0.00243632"/>
    </inertial>
    <visual>
      <origin rpy="0 0 0" xyz="0 0 0"/>
      <geometry>
        <mesh filename="../meshes/m6/Link5_L.STL"/>
      </geometry>
      <material name="">
        <color rgba="0.792156862745098 0.819607843137255 0.933333333333333 1"/>
      </material>
    </visual>
    <collision>
      <origin rpy="0 0 0" xyz="0 0 0"/>
      <geometry>
        <mesh filename="../meshes/m6/Link5_L.STL"/>
      </geometry>
    </collision>
  </link>
  <joint name="Joint5_L" type="revolute">
    <origin rpy="-1.5708 0 3.1416" xyz="0.018 -0.314 0"/>
    <parent link="Link4_L"/>
    <child link="Link5_L"/>
    <axis xyz="0 0 1"/>
    <limit effort="18" lower="-3.1067" upper="3.1067" velocity="3.1416"/>
  </joint>
  <link name="Link6_L">
    <inertial>
      <origin rpy="0 0 0" xyz="0.00032659 0.00531336 -0.00030182"/>
      <mass value="0.72496"/>
      <inertia ixx="0.00046040" ixy="0.00000189" ixz="0.00000083" iyy="0.00051716" iyz="-0.00000346" izz="0.00042521"/>
    </inertial>
    <visual>
      <origin rpy="0 0 0" xyz="0 0 0"/>
      <geometry>
        <mesh filename="../meshes/m6/Link6_L.STL"/>
      </geometry>
      <material name="">
        <color rgba="0.792156862745098 0.819607843137255 0.933333333333333 1"/>
      </material>
    </visual>
    <collision>
      <origin rpy="0 0 0" xyz="0 0 0"/>
      <geometry>
        <mesh filename="../meshes/m6/Link6_L.STL"/>
      </geometry>
    </collision>
  </link>
  <joint name="Joint6_L" type="revolute">
    <origin rpy="1.5708 -1.5708 0" xyz="0 0 0"/>
    <parent link="Link5_L"/>
    <child link="Link6_L"/>
    <axis xyz="0 0 1"/>
    <limit effort="18" lower="-1.0472" upper="1.0472" velocity="3.1416"/>
  </joint>
  <link name="Link7_L">
    <inertial>
      <origin rpy="0 0 0" xyz="-0.00009108 -0.03153255 0.00889371"/>
      <mass value="0.68606"/>
      <inertia ixx="0.00173687" ixy="-0.00000345" ixz="-0.00000116" iyy="0.00089035" iyz="0.00030680" izz="0.00139406"/>
    </inertial>
    <visual>
      <origin rpy="0 0 0" xyz="0 0 0"/>
      <geometry>
        <mesh filename="../meshes/m6/Link7_L.STL"/>
      </geometry>
      <material name="">
        <color rgba="0.792156862745098 0.819607843137255 0.933333333333333 1"/>
      </material>
    </visual>
    <collision>
      <origin rpy="0 0 0" xyz="0 0 0"/>
      <geometry>
        <mesh filename="../meshes/m6/Link7_L.STL"/>
      </geometry>
    </collision>
  </link>
  <joint name="Joint7_L" type="revolute">
    <origin rpy="1.5708 -1.5708 0" xyz="0 0 0"/>
    <parent link="Link6_L"/>
    <child link="Link7_L"/>
    <axis xyz="0 0 1"/>
    <limit effort="18" lower="-1.5708" upper="1.5708" velocity="3.1416"/>
  </joint>
  <link name="flange_L"/>
  <joint name="joint_flange_L" type="fixed">
    <origin rpy="1.5708 -1.5708 0" xyz="0.0 -0.088 0.0"/>
    <parent link="Link7_L"/>
    <child link="flange_L"/>
  </joint>
  <link name="Base_R">
    <inertial>
      <origin rpy="0 0 0" xyz="0.00032267 4.798E-05 0.04066353"/>
      <mass value="1.1962"/>
      <inertia ixx="0.00107329" ixy="-1.68E-06" ixz="-1.05E-05" iyy="0.00107003" iyz="-3.43E-06" izz="0.00127315"/>
    </inertial>
    <visual>
      <origin rpy="0 0 0" xyz="0 0 0"/>
      <geometry>
        <mesh filename="../meshes/m6/Base_R.STL"/>
      </geometry>
      <material name="">
        <color rgba="0.792156862745098 0.819607843137255 0.933333333333333 1"/>
      </material>
    </visual>
    <collision>
      <origin rpy="0 0 0" xyz="0 0 0"/>
      <geometry>
        <mesh filename="../meshes/m6/Base_R.STL"/>
      </geometry>
    </collision>
  </link>
  <link name="Link1_R">
    <inertial>
      <origin rpy="0 0 0" xyz="0.00002347 0.00557150 -0.03075998"/>
      <mass value="1.9705"/>
      <inertia ixx="0.00492293" ixy="0.00000550" ixz="0.00000193" iyy="0.00526513" iyz="0.00033232" izz="0.00188107"/>
    </inertial>
    <visual>
      <origin rpy="0 0 0" xyz="0 0 0"/>
      <geometry>
        <mesh filename="../meshes/m6/Link1_R.STL"/>
      </geometry>
      <material name="">
        <color rgba="0.792156862745098 0.819607843137255 0.933333333333333 1"/>
      </material>
    </visual>
    <collision>
      <origin rpy="0 0 0" xyz="0 0 0"/>
      <geometry>
        <mesh filename="../meshes/m6/Link1_R.STL"/>
      </geometry>
    </collision>
  </link>
  <joint name="Joint1_R" type="revolute">
    <origin rpy="0 0 0" xyz="0 0 0.1745"/>
    <parent link="Base_R"/>
    <child link="Link1_R"/>
    <axis xyz="0 0 1"/>
    <limit effort="108" lower="-3.1067" upper="3.1067" velocity="3.1416"/>
  </joint>
  <link name="Link2_R">
    <inertial>
      <origin rpy="0 0 0" xyz="0.00013483 0.06170460 0.00950639"/>
      <mass value="2.24398"/>
      <inertia ixx="0.01194933" ixy="0.00000336" ixz="0.00000091" iyy="0.00361581" iyz="-0.00132804" izz="0.01098356"/>
    </inertial>
    <visual>
      <origin rpy="0 0 0" xyz="0 0 0"/>
      <geometry>
        <mesh filename="../meshes/m6/Link2_R.STL"/>
      </geometry>
      <material name="">
        <color rgba="0.792156862745098 0.819607843137255 0.933333333333333 1"/>
      </material>
    </visual>
    <collision>
      <origin rpy="0 0 0" xyz="0 0 0"/>
      <geometry>
        <mesh filename="../meshes/m6/Link2_R.STL"/>
      </geometry>
    </collision>
  </link>
  <joint name="Joint2_R" type="revolute">
    <origin rpy="1.5708 0 0" xyz="0 0 0"/>
    <parent link="Link1_R"/>
    <child link="Link2_R"/>
    <axis xyz="0 0 1"/>
    <limit effort="108" lower="-2.0944" upper="2.0944" velocity="3.1416"/>
  </joint>
  <link name="Link3_R">
    <inertial>
      <origin rpy="0 0 0" xyz="0.00968562 0.00246599 -0.04627302"/>
      <mass value="1.9242"/>
      <inertia ixx="0.00718224" ixy="0.00004413" ixz="0.00089552" iyy="0.00762563" iyz="0.00022096" izz="0.00178597"/>
    </inertial>
    <visual>
      <origin rpy="0 0 0" xyz="0 0 0"/>
      <geometry>
        <mesh filename="../meshes/m6/Link3_R.STL"/>
      </geometry>
      <material name="">
        <color rgba="0.792156862745098 0.819607843137255 0.933333333333333 1"/>
      </material>
    </visual>
    <collision>
      <origin rpy="0 0 0" xyz="0 0 0"/>
      <geometry>
        <mesh filename="../meshes/m6/Link3_R.STL"/>
      </geometry>
    </collision>
  </link>
  <joint name="Joint3_R" type="revolute">
    <origin rpy="-1.5708 0 0" xyz="0 0.287 0"/>
    <parent link="Link2_R"/>
    <child link="Link3_R"/>
    <axis xyz="0 0 1"/>
    <limit effort="66" lower="-3.1067" upper="3.1067" velocity="3.1416"/>
  </joint>
  <link name="Link4_R">
    <inertial>
      <origin rpy="0 0 0" xyz="0.00850411 -0.04718223 0.00941509"/>
      <mass value="1.6085"/>
      <inertia ixx="0.00580480" ixy="-0.00066669" ixz="-0.00012722" iyy="0.00223807" iyz="0.00070523" izz="0.00533060"/>
    </inertial>
    <visual>
      <origin rpy="0 0 0" xyz="0 0 0"/>
      <geometry>
        <mesh filename="../meshes/m6/Link4_R.STL"/>
      </geometry>
      <material name="">
        <color rgba="0.792156862745098 0.819607843137255 0.933333333333333 1"/>
      </material>
    </visual>
    <collision>
      <origin rpy="0 0 0" xyz="0 0 0"/>
      <geometry>
        <mesh filename="../meshes/m6/Link4_R.STL"/>
      </geometry>
    </collision>
  </link>
  <joint name="Joint4_R" type="revolute">
    <origin rpy="-1.5708 0 3.1416" xyz="0.018 0 0"/>
    <parent link="Link3_R"/>
    <child link="Link4_R"/>
    <axis xyz="0 0 1"/>
    <limit effort="66" lower="-2.5307" upper="1.0472" velocity="3.1416"/>
  </joint>
  <link name="Link5_R">
    <inertial>
      <origin rpy="0 0 0" xyz="-0.00051127 -0.00101064 -0.11271739"/>
      <mass value="2.0883"/>
      <inertia ixx="0.00626603" ixy="0.00004009" ixz="-0.00005338" iyy="0.00564387" iyz="0.00006193" izz="0.00243632"/>
    </inertial>
    <visual>
      <origin rpy="0 0 0" xyz="0 0 0"/>
      <geometry>
        <mesh filename="../meshes/m6/Link5_R.STL"/>
      </geometry>
      <material name="">
        <color rgba="0.792156862745098 0.819607843137255 0.933333333333333 1"/>
      </material>
    </visual>
    <collision>
      <origin rpy="0 0 0" xyz="0 0 0"/>
      <geometry>
        <mesh filename="../meshes/m6/Link5_R.STL"/>
      </geometry>
    </collision>
  </link>
  <joint name="Joint5_R" type="revolute">
    <origin rpy="-1.5708 0 3.1416" xyz="0.018 -0.314 0"/>
    <parent link="Link4_R"/>
    <child link="Link5_R"/>
    <axis xyz="0 0 1"/>
    <limit effort="18" lower="-3.1067" upper="3.1067" velocity="3.1416"/>
  </joint>
  <link name="Link6_R">
    <inertial>
      <origin rpy="0 0 0" xyz="0.00032659 -0.00531336 0.00030182"/>
      <mass value="0.72496"/>
      <inertia ixx="0.00046040" ixy="-0.00000189" ixz="-0.00000083" iyy="0.00051716" iyz="-0.00000346" izz="0.00042521"/>
    </inertial>
    <visual>
      <origin rpy="0 0 0" xyz="0 0 0"/>
      <geometry>
        <mesh filename="../meshes/m6/Link6_R.STL"/>
      </geometry>
      <material name="">
        <color rgba="0.792156862745098 0.819607843137255 0.933333333333333 1"/>
      </material>
    </visual>
    <collision>
      <origin rpy="0 0 0" xyz="0 0 0"/>
      <geometry>
        <mesh filename="../meshes/m6/Link6_R.STL"/>
      </geometry>
    </collision>
  </link>
  <joint name="Joint6_R" type="revolute">
    <origin rpy="1.5708 -1.5708 0" xyz="0 0 0"/>
    <parent link="Link5_R"/>
    <child link="Link6_R"/>
    <axis xyz="0 0 1"/>
    <limit effort="18" lower="-1.0472" upper="1.0472" velocity="3.1416"/>
  </joint>
  <link name="Link7_R">
    <inertial>
      <origin rpy="0 0 0" xyz="-0.00009108 -0.03153255 0.00889371"/>
      <mass value="0.68606"/>
      <inertia ixx="0.00173687" ixy="-0.00000345" ixz="-0.00000116" iyy="0.00089035" iyz="0.00030680" izz="0.00139406"/>
    </inertial>
    <visual>
      <origin rpy="0 0 0" xyz="0 0 0"/>
      <geometry>
        <mesh filename="../meshes/m6/Link7_R.STL"/>
      </geometry>
      <material name="">
        <color rgba="0.792156862745098 0.819607843137255 0.933333333333333 1"/>
      </material>
    </visual>
    <collision>
      <origin rpy="0 0 0" xyz="0 0 0"/>
      <geometry>
        <mesh filename="../meshes/m6/Link7_R.STL"/>
      </geometry>
    </collision>
  </link>
  <joint name="Joint7_R" type="revolute">
    <origin rpy="1.5708 -1.5708 0" xyz="0 0 0"/>
    <parent link="Link6_R"/>
    <child link="Link7_R"/>
    <axis xyz="0 0 1"/>
    <limit effort="18" lower="-1.5708" upper="1.5708" velocity="3.1416"/>
  </joint>
  <link name="flange_R"/>
  <joint name="joint_flange_R" type="fixed">
    <origin rpy="1.5708 -1.5708 0" xyz="0.0 -0.088 0.0"/>
    <parent link="Link7_R"/>
    <child link="flange_R"/>
  </joint>
  <link name="base_link">
    <inertial>
      <origin rpy="0 0 0" xyz="-0.05101 -4.4993E-05 0.46366"/>
      <mass value="140.56"/>
      <inertia ixx="12.882" ixy="0.0053297" ixz="-0.78019" iyy="13.477" iyz="0.0054896" izz="2.3024"/>
    </inertial>
    <visual>
      <origin rpy="0 0 0" xyz="0 0 0"/>
      <geometry>
        <mesh filename="../meshes/Gento_Sky/Underpan_Base_link.STL"/>
      </geometry>
      <material name="">
        <color rgba="0.59216 0.61961 0.65098 1"/>
      </material>
    </visual>
    <collision>
      <origin rpy="0 0 0" xyz="0 0 0"/>
      <geometry>
        <mesh filename="../meshes/Gento_Sky/Underpan_Base_link.STL"/>
      </geometry>
    </collision>
  </link>
  <link name="left_front_wheel_Link_1">
    <inertial>
      <origin rpy="0 0 0" xyz="4.7248E-05 -0.024805 0.07456"/>
      <mass value="0.62536"/>
      <inertia ixx="0.000737" ixy="-1.7696E-08" ixz="-3.4083E-07" iyy="0.00056421" iyz="-0.00022951" izz="0.00050493"/>
    </inertial>
    <visual>
      <origin rpy="0 0 0" xyz="0 0 0"/>
      <geometry>
        <mesh filename="../meshes/Gento_Sky/left_front_wheel_Link_1.STL"/>
      </geometry>
      <material name="">
        <color rgba="0.89804 0.91765 0.92941 1"/>
      </material>
    </visual>
    <collision>
      <origin rpy="0 0 0" xyz="0 0 0"/>
      <geometry>
        <mesh filename="../meshes/Gento_Sky/left_front_wheel_Link_1.STL"/>
      </geometry>
    </collision>
  </link>
  <joint name="left_front wheel_joint_1" type="fixed">
    <origin rpy="0 0 0" xyz="0.23 0.218 0.07"/>
    <parent link="base_link"/>
    <child link="left_front_wheel_Link_1"/>
    <axis xyz="0 0 1"/>
    <limit effort="0" lower="-2.97" upper="2.97" velocity="6.28"/>
  </joint>
  <link name="left_front_wheel_Link_2">
    <inertial>
      <origin rpy="0 0 0" xyz="-2.452E-06 -1.127E-05 0.00050827"/>
      <mass value="1.2504"/>
      <inertia ixx="0.0020936" ixy="-1.2678E-08" ixz="8.0222E-08" iyy="0.0020939" iyz="-1.3183E-07" izz="0.0038354"/>
    </inertial>
    <visual>
      <origin rpy="0 0 0" xyz="0 0 0"/>
      <geometry>
        <mesh filename="../meshes/Gento_Sky/left_front_wheel_Link_2.STL"/>
      </geometry>
      <material name="">
        <color rgba="0.8902 0.8902 0.91373 1"/>
      </material>
    </visual>
    <collision>
      <origin rpy="0 0 0" xyz="0 0 0"/>
      <geometry>
        <mesh filename="../meshes/Gento_Sky/left_front_wheel_Link_2.STL"/>
      </geometry>
    </collision>
  </link>
  <joint name="left_front wheel_joint_2" type="fixed">
    <origin rpy="-1.5708 0 0" xyz="0 0 0"/>
    <parent link="left_front_wheel_Link_1"/>
    <child link="left_front_wheel_Link_2"/>
    <axis xyz="0 0 -1"/>
    <limit effort="0" lower="-2.97" upper="2.97" velocity="6.28"/>
  </joint>
  <link name="right_front_wheel_Link_1">
    <inertial>
      <origin rpy="0 0 0" xyz="-4.7248E-05 0.024805 0.07456"/>
      <mass value="0.62536"/>
      <inertia ixx="0.000737" ixy="-1.7694E-08" ixz="3.4083E-07" iyy="0.00056421" iyz="0.00022951" izz="0.00050493"/>
    </inertial>
    <visual>
      <origin rpy="0 0 0" xyz="0 0 0"/>
      <geometry>
        <mesh filename="../meshes/Gento_Sky/right_front_wheel_Link_1.STL"/>
      </geometry>
      <material name="">
        <color rgba="0.89804 0.91765 0.92941 1"/>
      </material>
    </visual>
    <collision>
      <origin rpy="0 0 0" xyz="0 0 0"/>
      <geometry>
        <mesh filename="../meshes/Gento_Sky/right_front_wheel_Link_1.STL"/>
      </geometry>
    </collision>
  </link>
  <joint name="right_front wheel_joint_1" type="fixed">
    <origin rpy="0 0 0" xyz="0.23 -0.218 0.07"/>
    <parent link="base_link"/>
    <child link="right_front_wheel_Link_1"/>
    <axis xyz="0 0 1"/>
    <limit effort="0" lower="-2.97" upper="2.97" velocity="6.28"/>
  </joint>
  <link name="right_front_wheel_Link_2">
    <inertial>
      <origin rpy="0 0 0" xyz="2.452E-06 -1.127E-05 -0.00050827"/>
      <mass value="1.2504"/>
      <inertia ixx="0.0020936" ixy="1.2678E-08" ixz="8.0222E-08" iyy="0.0020939" iyz="1.3183E-07" izz="0.0038354"/>
    </inertial>
    <visual>
      <origin rpy="0 0 0" xyz="0 0 0"/>
      <geometry>
        <mesh filename="../meshes/Gento_Sky/right_front_wheel_Link_2.STL"/>
      </geometry>
      <material name="">
        <color rgba="0.8902 0.8902 0.91373 1"/>
      </material>
    </visual>
    <collision>
      <origin rpy="0 0 0" xyz="0 0 0"/>
      <geometry>
        <mesh filename="../meshes/Gento_Sky/right_front_wheel_Link_2.STL"/>
      </geometry>
    </collision>
  </link>
  <joint name="right_front wheel_joint_2" type="fixed">
    <origin rpy="-1.5708 0 0" xyz="0 0 0"/>
    <parent link="right_front_wheel_Link_1"/>
    <child link="right_front_wheel_Link_2"/>
    <axis xyz="0 0 1"/>
    <limit effort="0" lower="-2.97" upper="2.97" velocity="6.28"/>
  </joint>
  <link name="left_back_wheel_Link_1">
    <inertial>
      <origin rpy="0 0 0" xyz="4.72480990756363E-05 -0.0248051423968753 0.0745596997023048"/>
      <mass value="0.625359297818115"/>
      <inertia ixx="0.00073700083969477" ixy="-1.76970193786471E-08" ixz="-3.40833146740822E-07" iyy="0.000564207634215223" iyz="-0.000229507675996817" izz="0.000504930064007062"/>
    </inertial>
    <visual>
      <origin rpy="0 0 0" xyz="0 0 0"/>
      <geometry>
        <mesh filename="../meshes/Gento_Sky/left_back_wheel_Link_1.STL"/>
      </geometry>
      <material name="">
        <color rgba="0.898039215686275 0.917647058823529 0.929411764705882 1"/>
      </material>
    </visual>
    <collision>
      <origin rpy="0 0 0" xyz="0 0 0"/>
      <geometry>
        <mesh filename="../meshes/Gento_Sky/left_back_wheel_Link_1.STL"/>
      </geometry>
    </collision>
  </link>
  <joint name="left_back wheel_joint_1" type="fixed">
    <origin rpy="0 0 0" xyz="-0.23 0.218 0.07"/>
    <parent link="base_link"/>
    <child link="left_back_wheel_Link_1"/>
    <axis xyz="0 0 1"/>
    <limit effort="0" lower="-2.97" upper="2.97" velocity="6.28"/>
  </joint>
  <link name="left_back_wheel_Link_2">
    <inertial>
      <origin rpy="0 0 0" xyz="-2.45199884629788E-06 -1.126982498156E-05 0.000508270150065854"/>
      <mass value="1.25042321080329"/>
      <inertia ixx="0.00209364819448314" ixy="-1.26783283227871E-08" ixz="8.02220562908989E-08" iyy="0.0020938760257053" iyz="-1.3182542191118E-07" izz="0.00383544895123036"/>
    </inertial>
    <visual>
      <origin rpy="0 0 0" xyz="0 0 0"/>
      <geometry>
        <mesh filename="../meshes/Gento_Sky/left_back_wheel_Link_2.STL"/>
      </geometry>
      <material name="">
        <color rgba="0.890196078431372 0.890196078431372 0.913725490196078 1"/>
      </material>
    </visual>
    <collision>
      <origin rpy="0 0 0" xyz="0 0 0"/>
      <geometry>
        <mesh filename="../meshes/Gento_Sky/left_back_wheel_Link_2.STL"/>
      </geometry>
    </collision>
  </link>
  <joint name="left_back wheel_joint_2" type="fixed">
    <origin rpy="-1.5708 0 0" xyz="0 0 0"/>
    <parent link="left_back_wheel_Link_1"/>
    <child link="left_back_wheel_Link_2"/>
    <axis xyz="0 0 -1"/>
    <limit effort="0" lower="-2.97" upper="2.97" velocity="6.28"/>
  </joint>
  <link name="right_back_wheel_Link_1">
    <inertial>
      <origin rpy="0 0 0" xyz="-4.72479201441833E-05 0.0248051425012648 0.0745596996435598"/>
      <mass value="0.625359293020441"/>
      <inertia ixx="0.000737000834389918" ixy="-1.76942751149633E-08" ixz="3.4083031481744E-07" iyy="0.000564207629212768" iyz="0.000229507673496893" izz="0.000504930059143131"/>
    </inertial>
    <visual>
      <origin rpy="0 0 0" xyz="0 0 0"/>
      <geometry>
        <mesh filename="../meshes/Gento_Sky/right_back_wheel_Link_1.STL"/>
      </geometry>
      <material name="">
        <color rgba="0.898039215686275 0.917647058823529 0.929411764705882 1"/>
      </material>
    </visual>
    <collision>
      <origin rpy="0 0 0" xyz="0 0 0"/>
      <geometry>
        <mesh filename="../meshes/Gento_Sky/right_back_wheel_Link_1.STL"/>
      </geometry>
    </collision>
  </link>
  <joint name="right_back wheel_joint_1" type="fixed">
    <origin rpy="0 0 0" xyz="-0.23 -0.218 0.07"/>
    <parent link="base_link"/>
    <child link="right_back_wheel_Link_1"/>
    <axis xyz="0 0 1"/>
    <limit effort="0" lower="-2.97" upper="2.97" velocity="6.28"/>
  </joint>
  <link name="right_back_wheel_Link_2">
    <inertial>
      <origin rpy="0 0 0" xyz="2.45199884629788E-06 -1.12698249817404E-05 -0.000508270150065659"/>
      <mass value="1.25042321080329"/>
      <inertia ixx="0.00209364819448314" ixy="1.26783283226824E-08" ixz="8.02220562907171E-08" iyy="0.0020938760257053" iyz="1.31825421908989E-07" izz="0.00383544895123036"/>
    </inertial>
    <visual>
      <origin rpy="0 0 0" xyz="0 0 0"/>
      <geometry>
        <mesh filename="../meshes/Gento_Sky/right_back_wheel_Link_2.STL"/>
      </geometry>
      <material name="">
        <color rgba="0.890196078431372 0.890196078431372 0.913725490196078 1"/>
      </material>
    </visual>
    <collision>
      <origin rpy="0 0 0" xyz="0 0 0"/>
      <geometry>
        <mesh filename="../meshes/Gento_Sky/right_back_wheel_Link_2.STL"/>
      </geometry>
    </collision>
  </link>
  <joint name="right_back wheel_joint_2" type="fixed">
    <origin rpy="-1.5708 0 0" xyz="0 0 0"/>
    <parent link="right_back_wheel_Link_1"/>
    <child link="right_back_wheel_Link_2"/>
    <axis xyz="0 0 1"/>
    <limit effort="0" lower="-2.97" upper="2.97" velocity="6.28"/>
  </joint>
  <link name="waist_Link_1_prismatic">
    <inertial>
      <origin rpy="0 0 0" xyz="-0.0430437093468533 -0.000990409500769455 -0.0031406743101291"/>
      <mass value="6.05415467108093"/>
      <inertia ixx="0.0138855670746497" ixy="0.000258195995213007" ixz="-0.00147166478552455" iyy="0.0418468499408627" iyz="1.87897375203689E-05" izz="0.036639938436386"/>
    </inertial>
    <visual>
      <origin rpy="0 0 0" xyz="0 0 0"/>
      <geometry>
        <mesh filename="../meshes/Gento_Sky/waist_Link_1_prismatic.STL"/>
      </geometry>
      <material name="">
        <color rgba="0.592156862745098 0.619607843137255 0.650980392156863 1"/>
      </material>
    </visual>
    <collision>
      <origin rpy="0 0 0" xyz="0 0 0"/>
      <geometry>
        <mesh filename="../meshes/Gento_Sky/waist_Link_1_prismatic.STL"/>
      </geometry>
    </collision>
  </link>
  <joint name="waist_joint_1" type="prismatic">
    <origin rpy="0 0 0" xyz="0.18048 0 0.36213"/>
    <parent link="base_link"/>
    <child link="waist_Link_1_prismatic"/>
    <axis xyz="0 0 1"/>
    <limit effort="0" lower="0" upper="0.86" velocity="0.2"/>
  </joint>
  <link name="waist_Link_2">
    <inertial>
      <origin rpy="0 0 0" xyz="0.0026398 0.022352 -0.0012175"/>
      <mass value="5.3546"/>
      <inertia ixx="0.018999" ixy="-0.00025673" ixz="-3.65E-05" iyy="0.017835" iyz="-0.00022272" izz="0.020053"/>
    </inertial>
    <visual>
      <origin rpy="0 0 0" xyz="0 0 0"/>
      <geometry>
        <mesh filename="../meshes/Gento_Sky/waist_Link_2.STL"/>
      </geometry>
      <material name="">
        <color rgba="0.59216 0.61961 0.65098 1"/>
      </material>
    </visual>
    <collision>
      <origin rpy="0 0 0" xyz="0 0 0"/>
      <geometry>
        <mesh filename="../meshes/Gento_Sky/waist_Link_2.STL"/>
      </geometry>
    </collision>
  </link>
  <joint name="waist_joint_2" type="revolute">
    <origin rpy="1.5708 0 0" xyz="0 0 0"/>
    <parent link="waist_Link_1_prismatic"/>
    <child link="waist_Link_2"/>
    <axis xyz="0 0 1"/>
    <limit effort="194" lower="-1.5708" upper="0" velocity="3.14"/>
  </joint>
  <link name="waist_Link_3">
    <inertial>
      <origin rpy="0 0 0" xyz="0.0044004 9.6396E-05 0.34103"/>
      <mass value="16.415"/>
      <inertia ixx="0.24229" ixy="3.2548E-05" ixz="-0.014747" iyy="0.24461" iyz="7.9231E-05" izz="0.099896"/>
    </inertial>
    <visual>
      <origin rpy="0 0 0" xyz="0 0 0"/>
      <geometry>
        <mesh filename="../meshes/Gento_Sky/waist_Link_3.STL"/>
      </geometry>
      <material name="">
        <color rgba="0.59216 0.61961 0.65098 1"/>
      </material>
    </visual>
    <collision>
      <origin rpy="0 0 0" xyz="0 0 0"/>
      <geometry>
        <mesh filename="../meshes/Gento_Sky/waist_Link_3.STL"/>
      </geometry>
    </collision>
  </link>
  <joint name="waist_joint_3" type="revolute">
    <origin rpy="-1.5708 0 0" xyz="0 0 0"/>
    <parent link="waist_Link_2"/>
    <child link="waist_Link_3"/>
    <axis xyz="0 0 1"/>
    <limit effort="194" lower="-0.4363" upper="0.4363" velocity="3.14"/>
  </joint>
  <link name="head_Link_1">
    <inertial>
      <origin rpy="0 0 0" xyz="-0.0003618 -0.012521 -0.017538"/>
      <mass value="1.3932"/>
      <inertia ixx="0.0032972" ixy="6.671E-06" ixz="-4.9572E-05" iyy="0.003207" iyz="0.00030601" izz="0.0016203"/>
    </inertial>
    <visual>
      <origin rpy="0 0 0" xyz="0 0 0"/>
      <geometry>
        <mesh filename="../meshes/Gento_Sky/head_Link_1.STL"/>
      </geometry>
      <material name="">
        <color rgba="0.59216 0.61961 0.65098 1"/>
      </material>
    </visual>
    <collision>
      <origin rpy="0 0 0" xyz="0 0 0"/>
      <geometry>
        <mesh filename="../meshes/Gento_Sky/head_Link_1.STL"/>
      </geometry>
    </collision>
  </link>
  <joint name="Head_J1_Joint" type="revolute">
    <origin rpy="0 0 0" xyz="-0.0135 0 0.648"/>
    <parent link="waist_Link_3"/>
    <child link="head_Link_1"/>
    <axis xyz="0 0 1"/>
    <limit effort="22" lower="-1.5708" upper="1.5708" velocity="3.14"/>
  </joint>
  <link name="head_Link_2">
    <inertial>
      <origin rpy="0 0 0" xyz="0.056578 0.029149 -0.018877"/>
      <mass value="1.0575"/>
      <inertia ixx="0.0041115" ixy="-0.00044589" ixz="-0.0004608" iyy="0.0028478" iyz="-0.00034534" izz="0.003764"/>
    </inertial>
    <visual>
      <origin rpy="0 0 0" xyz="0 0 0"/>
      <geometry>
        <mesh filename="../meshes/Gento_Sky/head_Link_2.STL"/>
      </geometry>
      <material name="">
        <color rgba="0.59216 0.61961 0.65098 1"/>
      </material>
    </visual>
    <collision>
      <origin rpy="0 0 0" xyz="0 0 0"/>
      <geometry>
        <mesh filename="../meshes/Gento_Sky/head_Link_2.STL"/>
      </geometry>
    </collision>
  </link>
  <joint name="Head_J2_Joint" type="revolute">
    <origin rpy="1.5708 0 0" xyz="0 0 0"/>
    <parent link="head_Link_1"/>
    <child link="head_Link_2"/>
    <axis xyz="0 0 -1"/>
    <limit effort="22" lower="-0.6109" upper="0.4363" velocity="3.14"/>
  </joint>
  <joint name="left_base_joint" type="fixed">
    <origin rpy="-1.5708 0 0" xyz="0 0.056 0.4335"/>
    <parent link="waist_Link_3"/>
    <child link="Base_L"/>
  </joint>
  <joint name="right_base_joint" type="fixed">
    <origin rpy="1.5708 0 0" xyz="0 -0.056 0.4335"/>
    <parent link="waist_Link_3"/>
    <child link="Base_R"/>
  </joint>
</robot>
