<?xml version='1.0' encoding='UTF-8'?>
<mujoco model="marvin_robot">
  <compiler angle="radian"/>

  <option timestep="0.001" integrator="implicitfast"/>


  <default>
  <default class="ccs_m6">
  <!--
  <general gaintype="fixed" biastype="affine" ctrlrange="-6.2831 6.2831" gainprm="2000" biasprm="0 -2000 -400"
          forcerange="-150 150"/> 
  -->
    <joint damping="2" armature="0.1" frictionloss="0.2"/>
    <position inheritrange="1"/>
    <default class="visual">
      <geom group="2" type="mesh" contype="0" conaffinity="0" rgba="0.3 0.3 0.3 1"/>
    </default>
    <default class="collision">
      <geom type="capsule" group="3" mass="0" density="0"/>
    </default>
    <default class="wuji_finger">
      <joint damping="0.0" armature="0.0002" frictionloss="0"/>
    </default>
  </default>
</default>

  <asset>
    <mesh name="Base_L" content_type="model/stl" file="../../meshes/marvin_pro/m6/Base_L.STL"/>
    <mesh name="Arm_L1_Link" content_type="model/stl" file="../../meshes/marvin_pro/m6/Arm_L1_Link.STL"/>
    <mesh name="Arm_L2_Link" content_type="model/stl" file="../../meshes/marvin_pro/m6/Arm_L2_Link.STL"/>
    <mesh name="Arm_L3_Link" content_type="model/stl" file="../../meshes/marvin_pro/m6/Arm_L3_Link.STL"/>
    <mesh name="Arm_L4_Link" content_type="model/stl" file="../../meshes/marvin_pro/m6/Arm_L4_Link.STL"/>
    <mesh name="Arm_L5_Link" content_type="model/stl" file="../../meshes/marvin_pro/m6/Arm_L5_Link.STL"/>
    <mesh name="Arm_L6_Link" content_type="model/stl" file="../../meshes/marvin_pro/m6/Arm_L6_Link.STL"/>
    <mesh name="Arm_L7_Link" content_type="model/stl" file="../../meshes/marvin_pro/m6/Arm_L7_Link.STL"/>
    <mesh name="Base_R" content_type="model/stl" file="../../meshes/marvin_pro/m6/Base_R.STL"/>
    <mesh name="Arm_R1_Link" content_type="model/stl" file="../../meshes/marvin_pro/m6/Arm_R1_Link.STL"/>
    <mesh name="Arm_R2_Link" content_type="model/stl" file="../../meshes/marvin_pro/m6/Arm_R2_Link.STL"/>
    <mesh name="Arm_R3_Link" content_type="model/stl" file="../../meshes/marvin_pro/m6/Arm_R3_Link.STL"/>
    <mesh name="Arm_R4_Link" content_type="model/stl" file="../../meshes/marvin_pro/m6/Arm_R4_Link.STL"/>
    <mesh name="Arm_R5_Link" content_type="model/stl" file="../../meshes/marvin_pro/m6/Arm_R5_Link.STL"/>
    <mesh name="Arm_R6_Link" content_type="model/stl" file="../../meshes/marvin_pro/m6/Arm_R6_Link.STL"/>
    <mesh name="Arm_R7_Link" content_type="model/stl" file="../../meshes/marvin_pro/m6/Arm_R7_Link.STL"/>
    <mesh name="ZJ_Robot_link" content_type="model/stl" file="../../meshes/marvin_pro/base/ZJ_Robot_link.STL"/>
    <mesh name="left_gripper_base_mesh" content_type="model/stl" file="../../meshes/marvin_pro/omnigripper/base_link.STL"/>
    <mesh name="left_gripper_left_finger_mesh" content_type="model/stl" file="../../meshes/marvin_pro/omnigripper/Left_Finger_Link.STL"/>
    <mesh name="left_gripper_right_finger_mesh" content_type="model/stl" file="../../meshes/marvin_pro/omnigripper/Right_Finger_Link.STL"/>
    <mesh name="right_gripper_base_mesh" content_type="model/stl" file="../../meshes/marvin_pro/omnigripper/base_link.STL"/>
    <mesh name="right_gripper_left_finger_mesh" content_type="model/stl" file="../../meshes/marvin_pro/omnigripper/Left_Finger_Link.STL"/>
    <mesh name="right_gripper_right_finger_mesh" content_type="model/stl" file="../../meshes/marvin_pro/omnigripper/Right_Finger_Link.STL"/>
    <!-- Wuji left-hand meshes (mounted for left gripper) -->
    <mesh name="left_palm_link" content_type="model/stl" file="../../../wuji-hand-description/meshes/left/left_palm_link.STL"/>
    <mesh name="left_finger1_link1" content_type="model/stl" file="../../../wuji-hand-description/meshes/left/left_finger1_link1.STL"/>
    <mesh name="left_finger1_link2" content_type="model/stl" file="../../../wuji-hand-description/meshes/left/left_finger1_link2.STL"/>
    <mesh name="left_finger1_link3" content_type="model/stl" file="../../../wuji-hand-description/meshes/left/left_finger1_link3.STL"/>
    <mesh name="left_finger1_link4" content_type="model/stl" file="../../../wuji-hand-description/meshes/left/left_finger1_link4.STL"/>
    <mesh name="left_finger1_tip_link" content_type="model/stl" file="../../../wuji-hand-description/meshes/left/left_finger1_tip_link.STL"/>
    <mesh name="left_finger2_link1" content_type="model/stl" file="../../../wuji-hand-description/meshes/left/left_finger2_link1.STL"/>
    <mesh name="left_finger2_link2" content_type="model/stl" file="../../../wuji-hand-description/meshes/left/left_finger2_link2.STL"/>
    <mesh name="left_finger2_link3" content_type="model/stl" file="../../../wuji-hand-description/meshes/left/left_finger2_link3.STL"/>
    <mesh name="left_finger2_link4" content_type="model/stl" file="../../../wuji-hand-description/meshes/left/left_finger2_link4.STL"/>
    <mesh name="left_finger2_tip_link" content_type="model/stl" file="../../../wuji-hand-description/meshes/left/left_finger2_tip_link.STL"/>
    <mesh name="left_finger3_link1" content_type="model/stl" file="../../../wuji-hand-description/meshes/left/left_finger3_link1.STL"/>
    <mesh name="left_finger3_link2" content_type="model/stl" file="../../../wuji-hand-description/meshes/left/left_finger3_link2.STL"/>
    <mesh name="left_finger3_link3" content_type="model/stl" file="../../../wuji-hand-description/meshes/left/left_finger3_link3.STL"/>
    <mesh name="left_finger3_link4" content_type="model/stl" file="../../../wuji-hand-description/meshes/left/left_finger3_link4.STL"/>
    <mesh name="left_finger3_tip_link" content_type="model/stl" file="../../../wuji-hand-description/meshes/left/left_finger3_tip_link.STL"/>
    <mesh name="left_finger4_link1" content_type="model/stl" file="../../../wuji-hand-description/meshes/left/left_finger4_link1.STL"/>
    <mesh name="left_finger4_link2" content_type="model/stl" file="../../../wuji-hand-description/meshes/left/left_finger4_link2.STL"/>
    <mesh name="left_finger4_link3" content_type="model/stl" file="../../../wuji-hand-description/meshes/left/left_finger4_link3.STL"/>
    <mesh name="left_finger4_link4" content_type="model/stl" file="../../../wuji-hand-description/meshes/left/left_finger4_link4.STL"/>
    <mesh name="left_finger4_tip_link" content_type="model/stl" file="../../../wuji-hand-description/meshes/left/left_finger4_tip_link.STL"/>
    <mesh name="left_finger5_link1" content_type="model/stl" file="../../../wuji-hand-description/meshes/left/left_finger5_link1.STL"/>
    <mesh name="left_finger5_link2" content_type="model/stl" file="../../../wuji-hand-description/meshes/left/left_finger5_link2.STL"/>
    <mesh name="left_finger5_link3" content_type="model/stl" file="../../../wuji-hand-description/meshes/left/left_finger5_link3.STL"/>
    <mesh name="left_finger5_link4" content_type="model/stl" file="../../../wuji-hand-description/meshes/left/left_finger5_link4.STL"/>
    <mesh name="left_finger5_tip_link" content_type="model/stl" file="../../../wuji-hand-description/meshes/left/left_finger5_tip_link.STL"/>
    <material name="gripper_base_mat" rgba="0.7922 0.8196 0.9294 1" specular="0"/>
    <material name="gripper_finger_mat" rgba="0.6039 0.6039 0.6039 1" specular="0"/>
  </asset>
  <contact>
    <exclude body1="base_link" body2="Base_L"/>
    <exclude body1="base_link" body2="Base_R"/>
    <exclude body1="Base_L" body2="Arm_L1_Link"/>
    <exclude body1="Arm_L1_Link" body2="Arm_L2_Link"/>
    <exclude body1="Arm_L2_Link" body2="Arm_L3_Link"/>
    <exclude body1="Arm_L3_Link" body2="Arm_L4_Link"/>
    <exclude body1="Arm_L4_Link" body2="Arm_L5_Link"/>
    <exclude body1="Arm_L5_Link" body2="Arm_L6_Link"/>
    <exclude body1="Arm_L6_Link" body2="Arm_L7_Link"/>
    <exclude body1="Base_R" body2="Arm_R1_Link"/>
    <exclude body1="Arm_R1_Link" body2="Arm_R2_Link"/>
    <exclude body1="Arm_R2_Link" body2="Arm_R3_Link"/>
    <exclude body1="Arm_R3_Link" body2="Arm_R4_Link"/>
    <exclude body1="Arm_R4_Link" body2="Arm_R5_Link"/>
    <exclude body1="Arm_R5_Link" body2="Arm_R6_Link"/>
    <exclude body1="Arm_R6_Link" body2="Arm_R7_Link"/>
    <exclude body1="Arm_L7_Link" body2="left_palm_link"/>
    <exclude body1="Arm_L7_Link" body2="left_finger1_link1"/>
    <exclude body1="Arm_L7_Link" body2="left_finger2_link1"/>
    <exclude body1="Arm_L7_Link" body2="left_finger3_link1"/>
    <exclude body1="Arm_L7_Link" body2="left_finger4_link1"/>
    <exclude body1="Arm_L7_Link" body2="left_finger5_link1"/>
    <exclude body1="left_palm_link" body2="left_finger1_link1"/>
    <exclude body1="left_palm_link" body2="left_finger2_link1"/>
    <exclude body1="left_palm_link" body2="left_finger3_link1"/>
    <exclude body1="left_palm_link" body2="left_finger4_link1"/>
    <exclude body1="left_palm_link" body2="left_finger5_link1"/>
    <exclude body1="Arm_R7_Link" body2="right_gripper_base"/>
    <exclude body1="Arm_R7_Link" body2="right_gripper_left_finger"/>
    <exclude body1="Arm_R7_Link" body2="right_gripper_right_finger"/>
    <exclude body1="right_gripper_base" body2="right_gripper_left_finger"/>
    <exclude body1="right_gripper_base" body2="right_gripper_right_finger"/>
    <exclude body1="right_gripper_left_finger" body2="right_gripper_right_finger"/>
  </contact>
  <equality>
    <joint joint1="right_gripper_right_finger_joint" joint2="right_gripper_left_finger_joint" polycoef="0 1 0 0 0"/>
  </equality>
  <worldbody>
    <body name="base_link" childclass="ccs_m6">
      <inertial pos="0.0081994 -5.1239e-06 0.47835" quat="0.999994 2.57224e-05 0.0031361 0.00173711" mass="18.846" diaginertia="0.463463 0.46325 0.377657"/>
      <geom class="visual"  rgba="0.8 0.8 0.8 1" mesh="ZJ_Robot_link"/>
      <geom name="base_link_collision" class="collision"  rgba="1 0 0 1" fromto="0 0 0 0 0 1.3" size="0.10"/>
      <body name="tracking_base_link" pos="0 0 -0.1"/>
        <camera name="head_left_camera" pos="0.086 0.015 1.218" xyaxes="0 -1 0 0.5 0 0.85" fovy="105"/>
        <camera name="head_right_camera" pos="0.086 -0.015 1.218" xyaxes="0 -1 0 0.5 0 0.85" fovy="105"/>
      <body name="Base_L" pos="0 0.026 1.121" quat="0.707388 -0.706825 0 0">
        <inertial pos="0.00032267 4.798e-05 0.0406635" quat="0.582787 0.36644 -0.620273 0.375956" mass="1.1962" diaginertia="0.00127375 0.00107367 0.00106904"/>
        <geom class="visual"  rgba="1 0 0 1" mesh="Base_L"/>
        <geom class="collision"  rgba="1 0 0 1" mesh="Base_L"/>
        <body name="Arm_L1_Link" pos="0 0 0.1745">
          <inertial pos="2.347e-05 0.0055715 -0.03076" quat="0.711599 0.0343691 -0.0341702 0.700912" mass="1.9705" diaginertia="0.00529754 0.00492285 0.00184874"/>
          <joint name="Arm_L1_Joint" pos="0 0 0" axis="0 0 1" range="-3.1067 3.1067" actuatorfrcrange="-108 108" damping="3" armature="0.15" frictionloss="0.3"/>
          <geom class="visual"  rgba="0 1 0 1" mesh="Arm_L1_Link"/>
          <geom class="collision"  rgba="0 1 0 1" mesh="Arm_L1_Link"/>
          <body name="Arm_L2_Link" quat="0.707105 0.707108 0 0">
            <inertial pos="0.00013483 0.0617046 0.00950639" quat="0.643375 0.765551 -3.57328e-05 0.000294349" mass="2.24398" diaginertia="0.0119493 0.0112156 0.00338374"/>
            <joint name="Arm_L2_Joint" pos="0 0 0" axis="0 0 1" range="-2.0944 -0.1" actuatorfrcrange="-108 108" damping="3" armature="0.15" frictionloss="0.3"/>
            <geom class="visual"  rgba="0 0 1 1" mesh="Arm_L2_Link"/>
            <geom class="collision"  rgba="0 0 1 1" mesh="Arm_L2_Link"/>
            <body name="Arm_L3_Link" pos="0 0.287 0" quat="0.707105 -0.707108 0 0">
              <inertial pos="0.00968562 0.00246599 -0.046273" quat="0.782446 -0.0355285 -0.0735516 0.617337" mass="1.9242" diaginertia="0.00765215 0.00730789 0.0016338"/>
              <joint name="Arm_L3_Joint" pos="0 0 0" axis="0 0 1" range="-3.1067 3.1067" actuatorfrcrange="-66 66" damping="2.5" armature="0.12" frictionloss="0.25"/>
              <geom class="visual"  rgba="1 0 0 1" mesh="Arm_L3_Link"/>
              <geom class="collision"  rgba="1 0 0 1" mesh="Arm_L3_Link"/>
              <body name="Arm_L4_Link" pos="0.018 0 0" quat="-2.59734e-06 2.59735e-06 -0.707108 0.707105">
                <inertial pos="0.00850411 -0.0471822 0.00941509" quat="0.741754 0.628694 0.0774999 -0.220317" mass="1.6085" diaginertia="0.00603244 0.00535875 0.00198228"/>
                <joint name="Arm_L4_Joint" pos="0 0 0" axis="0 0 1" range="-2.5307 -0.1" actuatorfrcrange="-66 66" damping="2.5" armature="0.12" frictionloss="0.25"/>
                <geom class="visual"  rgba="0 1 0 1" mesh="Arm_L4_Link"/>
                <geom name="Arm_L4_Link_collision" class="collision"  rgba="0 1 0 1" mesh="Arm_L4_Link"/>
                <body name="Arm_L5_Link" pos="0.018 -0.314 0" quat="-2.59734e-06 2.59735e-06 -0.707108 0.707105">
                  <inertial pos="0.00051127 0.00101064 -0.112717" quat="0.999438 -0.00995046 -0.00675781 0.0312997" mass="2.0883" diaginertia="0.00626924 0.00564262 0.00243436"/>
                  <joint name="Arm_L5_Joint" pos="0 0 0" axis="0 0 1" range="-3.1067 3.1067" actuatorfrcrange="-18 18" damping="1.5" armature="0.08" frictionloss="0.15"/>
                  <geom class="visual"  rgba="0 0 1 1" mesh="Arm_L5_Link"/>
                  <geom name="Arm_L5_Link_collision" class="collision"  rgba="0 0 1 1" fromto="0 0 0 0 0 -0.15" size="0.06"/>
                  <body name="Arm_L6_Link" quat="0.499998 0.5 -0.5 0.500002">
                    <inertial pos="0.00032659 0.00531336 -0.00030182" quat="0.718188 -0.0225408 0.00407878 0.695472" mass="0.72496" diaginertia="0.000517351 0.000460362 0.000425057"/>
                    <joint name="Arm_L6_Joint" pos="0 0 0" axis="0 0 1" range="-1.0472 1.0472" actuatorfrcrange="-18 18" damping="1.2" armature="0.06" frictionloss="0.12"/>
                    <geom class="visual"  rgba="1 0 0 1" mesh="Arm_L6_Link"/>
                    <geom class="collision"  rgba="1 0 0 1" mesh="Arm_L6_Link"/>
                    <body name="Arm_L7_Link" quat="0.499998 0.5 -0.5 0.500002">
                      <inertial pos="-9.108e-05 -0.0315325 0.00889371" quat="0.84481 0.535026 0.00229584 -0.00609725" mass="0.68606" diaginertia="0.00173691 0.00153911 0.000745263"/>
                      <joint name="Arm_L7_Joint" pos="0 0 0" axis="0 0 1" range="-1.5708 1.5708" actuatorfrcrange="-18 18" damping="1.2" armature="0.05" frictionloss="0.1"/>
                      <geom class="visual"  rgba="0 1 0 1" mesh="Arm_L7_Link"/>
                      <geom class="collision"  rgba="0 1 0 1" mesh="Arm_L7_Link"/>
                      <body name="flange_L" pos="0 -0.088 0" quat="0.499998 0.5 -0.5 0.500002">
                        <body name="left_gripper_mount" pos="0 0 0" quat="0.7071068 0 0 -0.7071068">
                          <body name="left_gripper_base" pos="0 0 0">
                            <inertial pos="-0.000142 0.005641 0.0488811" mass="0.4064271" fullinertia="0.0002976 0.0004831 0.0004721 -0.0000024 0.0000011 -0.0000721"/>
                            <camera name="left_wrist_camera" pos="0.01 0.01 0.115" xyaxes="-1 0 0 0 0.7 0.866" fovy="105"/>
                            <!-- Wuji left hand mounted here -->
                            <body name="left_palm_link"><inertial pos="-0.00297879327955292 -0.000452550870710431 0.0366547088987225" mass="0.16914" quat="-0.01772809 -0.04274722 0.09308295 0.99458230" diaginertia="1.40677446e-04 9.58896475e-05 5.81329061e-05" />
      <geom type="mesh" contype="0" conaffinity="0" group="1" density="0" rgba="0.6 0.8 0.9 1" mesh="left_palm_link" />
      <geom type="mesh" rgba="0.6 0.8 0.9 1" mesh="left_palm_link" contype="1" conaffinity="1" />
      <body name="left_finger1_link1" pos="0.0084399 -0.020587 0.028893" quat="0.682219 0.617669 0.0805047 0.382859">
        <inertial pos="-0.00246636 0.00124336 0.00779645" quat="0.904243 0.21652 0.0443878 -0.365368" mass="0.0075" diaginertia="3.37599e-07 3.01198e-07 2.11203e-07" />
        <joint name="left_finger1_joint1" class="wuji_finger" pos="0 0 0" axis="0 1 0" range="0.0475 1.6033" actuatorfrcrange="-0.4452 0.4452" armature="0.0005" />
        <geom type="mesh" contype="0" conaffinity="0" group="1" density="0" rgba="0.7 0.7 0.7 1" mesh="left_finger1_link1" />
        <geom type="mesh" rgba="0.7 0.7 0.7 1" mesh="left_finger1_link1" contype="0" conaffinity="0" />
        <body name="left_finger1_link2" pos="-0.0047549 0.0058191 0.014132" quat="0.616955 0.0855901 -0.290851 -0.726255">
          <inertial pos="0.00116592 1.46603e-05 0.015656" quat="0.815906 0.0024483 -0.00462559 0.57816" mass="0.0248" diaginertia="2.81725e-06 2.75299e-06 6.79766e-07" />
          <joint name="left_finger1_joint2" class="wuji_finger" pos="0 0 0" axis="0 -1 0" range="-0.1387 0.9324" actuatorfrcrange="-0.4259 0.4259" armature="0.0005" />
          <geom type="mesh" contype="0" conaffinity="0" group="1" density="0" rgba="0.9 0.8 0.6 1" mesh="left_finger1_link2" />
          <geom type="mesh" rgba="0.9 0.8 0.6 1" mesh="left_finger1_link2" contype="2" conaffinity="2" />
          <body name="left_finger1_link3" pos="0.00026671 0.0009915 0.034666" quat="0.577852 -0.0212383 -0.0150031 0.815727">
            <inertial pos="-0.0011232 1.57299e-05 0.0130566" quat="0.999951 0 0.00989566 0" mass="0.0165" diaginertia="1.4604e-06 1.42e-06 4.49604e-07" />
            <joint name="left_finger1_joint3" class="wuji_finger" pos="0 0 0" axis="0 1 0" range="-0.4642 1.5623" actuatorfrcrange="-0.1888 0.1888" />
            <geom type="mesh" contype="0" conaffinity="0" group="1" density="0" rgba="0.6 0.8 0.9 1" mesh="left_finger1_link3" />
            <geom type="mesh" rgba="0.6 0.8 0.9 1" mesh="left_finger1_link3" contype="1" conaffinity="1" />
            <body name="left_finger1_link4" pos="0 -0.0002 0.0295">
              <inertial pos="-0.00163886 0.000214814 0.0113475" quat="0.705316 -0.0503617 -0.0502939 0.705311" mass="0.0206" diaginertia="2.60196e-06 2.58216e-06 7.598e-07" />
              <joint name="left_finger1_joint4" class="wuji_finger" pos="0 0 0" axis="0 1 0" range="-0.4699 1.5568" actuatorfrcrange="-0.1468 0.1468" />
              <geom type="mesh" contype="0" conaffinity="0" group="1" density="0" rgba="0.6 0.8 0.9 1" mesh="left_finger1_link4" />
              <geom type="mesh" rgba="0.6 0.8 0.9 1" mesh="left_finger1_link4" contype="1" conaffinity="1" />
              <geom pos="-0.00105 0.0002 0.0313" type="mesh" contype="0" conaffinity="0" group="1" density="0" rgba="0.6 0.8 0.9 1" mesh="left_finger1_tip_link" />
              <geom pos="-0.00105 0.0002 0.0313" type="mesh" rgba="0.6 0.8 0.9 1" mesh="left_finger1_tip_link" contype="1" conaffinity="1" />
            </body>
          </body>
        </body>
      </body>
      <body name="left_finger2_link1" pos="-0.0058701 -0.029434 0.091917" quat="0.991689 0.0588295 -0.0292755 0.110614">
        <inertial pos="-0.0013291 -5.6587e-09 0.00031994" quat="0.92388 0 0.382683 0" mass="0.0032" diaginertia="1.1e-07 7e-08 5e-08" />
        <joint name="left_finger2_joint1" class="wuji_finger" pos="0 0 0" axis="0 1 0" range="-0.1585 1.5604" actuatorfrcrange="-0.6188 0.6188" armature="0.0005" />
        <geom type="mesh" contype="0" conaffinity="0" group="1" density="0" rgba="0.7 0.7 0.7 1" mesh="left_finger2_link1" />
        <geom type="mesh" rgba="0.7 0.7 0.7 1" mesh="left_finger2_link1" contype="0" conaffinity="0" />
        <body name="left_finger2_link2" pos="0.0022 0 0.00400001" quat="0.707107 0 0 0.707107">
          <inertial pos="4.37869e-07 0.00615752 0.020911" quat="0.70703 0.0104245 0.0104245 0.70703" mass="0.033" diaginertia="6.34e-06 6.31472e-06 8.85281e-07" />
          <joint name="left_finger2_joint2" class="wuji_finger" pos="0 0 0" axis="0 1 0" range="-0.37 0.37" actuatorfrcrange="-0.1822 0.1822" />
          <geom type="mesh" contype="0" conaffinity="0" group="1" density="0" rgba="0.9 0.8 0.6 1" mesh="left_finger2_link2" />
          <geom type="mesh" rgba="0.9 0.8 0.6 1" mesh="left_finger2_link2" contype="2" conaffinity="2" />
          <body name="left_finger2_link3" pos="0 0.00475 0.0436177" quat="0.707202 0 0 -0.707012">
            <inertial pos="-0.00112187 3.27619e-05 0.0157188" quat="0.999892 0 -0.0146884 0" mass="0.0165" diaginertia="1.47088e-06 1.44e-06 4.49118e-07" />
            <joint name="left_finger2_joint3" class="wuji_finger" pos="0 0 0" axis="0 1 0" range="-0.4777 1.5485" actuatorfrcrange="-0.2251 0.2251" />
            <geom type="mesh" contype="0" conaffinity="0" group="1" density="0" rgba="0.6 0.8 0.9 1" mesh="left_finger2_link3" />
            <geom type="mesh" rgba="0.6 0.8 0.9 1" mesh="left_finger2_link3" contype="1" conaffinity="1" />
            <body name="left_finger2_link4" pos="0 -0.0002 0.0295">
              <inertial pos="-0.000802981 -1.72016e-05 0.00761201" quat="0.998028 0.01288 -0.055568 0.0261826" mass="0.01718" diaginertia="1.55462e-06 1.45763e-06 4.20116e-07" />
              <joint name="left_finger2_joint4" class="wuji_finger" pos="0 0 0" axis="0 1 0" range="-0.4683 1.5753" actuatorfrcrange="-0.217 0.217" />
              <geom type="mesh" contype="0" conaffinity="0" group="1" density="0" rgba="0.6 0.8 0.9 1" mesh="left_finger2_link4" />
              <geom type="mesh" rgba="0.6 0.8 0.9 1" mesh="left_finger2_link4" contype="1" conaffinity="1" />
              <geom pos="-0.0010521 0.000210869 0.0267" type="mesh" contype="0" conaffinity="0" group="1" density="0" rgba="0.6 0.8 0.9 1" mesh="left_finger2_tip_link" />
              <geom pos="-0.0010521 0.000210869 0.0267" type="mesh" rgba="0.6 0.8 0.9 1" mesh="left_finger2_tip_link" contype="1" conaffinity="1" />
            </body>
          </body>
        </body>
      </body>
      <body name="left_finger3_link1" pos="-0.01046 -0.0074615 0.089544" quat="0.999048 1.26888e-05 -0.0436192 -0.000290547">
        <inertial pos="-0.0013291 -1.4994e-08 0.0003199" quat="0.92388 0 0.382683 0" mass="0.0032" diaginertia="1.1e-07 7e-08 5e-08" />
        <joint name="left_finger3_joint1" class="wuji_finger" pos="0 0 0" axis="0 1 0" range="-0.1644 1.5516" actuatorfrcrange="-0.6494 0.6494" armature="0.0005" />
        <geom type="mesh" contype="0" conaffinity="0" group="1" density="0" rgba="0.7 0.7 0.7 1" mesh="left_finger3_link1" />
        <geom type="mesh" rgba="0.7 0.7 0.7 1" mesh="left_finger3_link1" contype="0" conaffinity="0" />
        <body name="left_finger3_link2" pos="0.0022 0 0.00400001" quat="0.707107 0 0 0.707107">
          <inertial pos="4.38062e-07 0.00615753 0.020911" quat="0.70703 0.0104245 0.0104245 0.70703" mass="0.033" diaginertia="6.34e-06 6.31472e-06 8.85281e-07" />
          <joint name="left_finger3_joint2" class="wuji_finger" pos="0 0 0" axis="0 1 0" range="-0.37 0.37" actuatorfrcrange="-0.1827 0.1827" />
          <geom type="mesh" contype="0" conaffinity="0" group="1" density="0" rgba="0.9 0.8 0.6 1" mesh="left_finger3_link2" />
          <geom type="mesh" rgba="0.9 0.8 0.6 1" mesh="left_finger3_link2" contype="2" conaffinity="2" />
          <body name="left_finger3_link3" pos="0 0.00475 0.0436177" quat="0.707202 0 0 -0.707012">
            <inertial pos="-0.00112187 3.27807e-05 0.0157188" quat="0.999892 0 -0.0146884 0" mass="0.0165" diaginertia="1.47088e-06 1.44e-06 4.49118e-07" />
            <joint name="left_finger3_joint3" class="wuji_finger" pos="0 0 0" axis="0 1 0" range="-0.4739 1.5512" actuatorfrcrange="-0.2078 0.2078" />
            <geom type="mesh" contype="0" conaffinity="0" group="1" density="0" rgba="0.6 0.8 0.9 1" mesh="left_finger3_link3" />
            <geom type="mesh" rgba="0.6 0.8 0.9 1" mesh="left_finger3_link3" contype="1" conaffinity="1" />
            <body name="left_finger3_link4" pos="0 -0.0002 0.0295">
              <inertial pos="-0.000801449 -1.76824e-05 0.00761202" quat="0.998029 0.0129107 -0.0554603 0.026365" mass="0.01718" diaginertia="1.55458e-06 1.45766e-06 4.20206e-07" />
              <joint name="left_finger3_joint4" class="wuji_finger" pos="0 0 0" axis="0 1 0" range="-0.4684 1.5745" actuatorfrcrange="-0.2018 0.2018" />
              <geom type="mesh" contype="0" conaffinity="0" group="1" density="0" rgba="0.6 0.8 0.9 1" mesh="left_finger3_link4" />
              <geom type="mesh" rgba="0.6 0.8 0.9 1" mesh="left_finger3_link4" contype="1" conaffinity="1" />
              <geom pos="-0.0010504 0.000202672 0.0267" type="mesh" contype="0" conaffinity="0" group="1" density="0" rgba="0.6 0.8 0.9 1" mesh="left_finger3_tip_link" />
              <geom pos="-0.0010504 0.000202672 0.0267" type="mesh" rgba="0.6 0.8 0.9 1" mesh="left_finger3_tip_link" contype="1" conaffinity="1" />
            </body>
          </body>
        </body>
      </body>
      <body name="left_finger4_link1" pos="-0.0076649 0.013712 0.084429" quat="0.997789 -0.0461019 -0.0405884 -0.0254002">
        <inertial pos="-0.0013291 -9.6993e-09 0.00031986" quat="0.92388 0 0.382683 0" mass="0.0032" diaginertia="1.1e-07 7e-08 5e-08" />
        <joint name="left_finger4_joint1" class="wuji_finger" pos="0 0 0" axis="0 1 0" range="-0.1554 1.5585" actuatorfrcrange="-0.6389 0.6389" armature="0.0005" />
        <geom type="mesh" contype="0" conaffinity="0" group="1" density="0" rgba="0.7 0.7 0.7 1" mesh="left_finger4_link1" />
        <geom type="mesh" rgba="0.7 0.7 0.7 1" mesh="left_finger4_link1" contype="0" conaffinity="0" />
        <body name="left_finger4_link2" pos="0.0022 0 0.00400001" quat="0.707107 0 0 0.707107">
          <inertial pos="4.36896e-07 0.00615754 0.020911" quat="0.70703 0.0104245 0.0104245 0.70703" mass="0.033" diaginertia="6.34e-06 6.31472e-06 8.85281e-07" />
          <joint name="left_finger4_joint2" class="wuji_finger" pos="0 0 0" axis="0 1 0" range="-0.37 0.37" actuatorfrcrange="-0.1832 0.1832" />
          <geom type="mesh" contype="0" conaffinity="0" group="1" density="0" rgba="0.9 0.8 0.6 1" mesh="left_finger4_link2" />
          <geom type="mesh" rgba="0.9 0.8 0.6 1" mesh="left_finger4_link2" contype="2" conaffinity="2" />
          <body name="left_finger4_link3" pos="0 0.00475 0.0436177" quat="0.707202 0 0 -0.707012">
            <inertial pos="-0.00112188 3.27942e-05 0.0157188" quat="0.999892 0 -0.0146884 0" mass="0.0165" diaginertia="1.47088e-06 1.44e-06 4.49118e-07" />
            <joint name="left_finger4_joint3" class="wuji_finger" pos="0 0 0" axis="0 1 0" range="-0.4765 1.5487" actuatorfrcrange="-0.2249 0.2249" />
            <geom type="mesh" contype="0" conaffinity="0" group="1" density="0" rgba="0.6 0.8 0.9 1" mesh="left_finger4_link3" />
            <geom type="mesh" rgba="0.6 0.8 0.9 1" mesh="left_finger4_link3" contype="1" conaffinity="1" />
            <body name="left_finger4_link4" pos="0 -0.0002 0.0295">
              <inertial pos="-0.000801408 -1.86048e-05 0.00761203" quat="0.998025 0.012979 -0.0554598 0.0264871" mass="0.01718" diaginertia="1.55462e-06 1.45766e-06 4.20231e-07" />
              <joint name="left_finger4_joint4" class="wuji_finger" pos="0 0 0" axis="0 1 0" range="-0.4777 1.5634" actuatorfrcrange="-0.2044 0.2044" />
              <geom type="mesh" contype="0" conaffinity="0" group="1" density="0" rgba="0.6 0.8 0.9 1" mesh="left_finger4_link4" />
              <geom type="mesh" rgba="0.6 0.8 0.9 1" mesh="left_finger4_link4" contype="1" conaffinity="1" />
              <geom pos="-0.00104998 0.000202557 0.0267" type="mesh" contype="0" conaffinity="0" group="1" density="0" rgba="0.6 0.8 0.9 1" mesh="left_finger4_tip_link" />
              <geom pos="-0.00104998 0.000202557 0.0267" type="mesh" rgba="0.6 0.8 0.9 1" mesh="left_finger4_tip_link" contype="1" conaffinity="1" />
            </body>
          </body>
        </body>
      </body>
      <body name="left_finger5_link1" pos="-0.00226865 0.0340011 0.0742813" quat="0.990869 -0.0993173 -0.0383255 -0.0827362">
        <inertial pos="-0.00132909 -2.35275e-08 0.000319845" quat="0.92388 0 0.382683 0" mass="0.0032" diaginertia="1.1e-07 7e-08 5e-08" />
        <joint name="left_finger5_joint1" class="wuji_finger" pos="0 0 0" axis="0 1 0" range="-0.1626 1.5585" actuatorfrcrange="-0.6441 0.6441" armature="0.0005" />
        <geom type="mesh" contype="0" conaffinity="0" group="1" density="0" rgba="0.7 0.7 0.7 1" mesh="left_finger5_link1" />
        <geom type="mesh" rgba="0.7 0.7 0.7 1" mesh="left_finger5_link1" contype="0" conaffinity="0" />
        <body name="left_finger5_link2" pos="0.0022 0 0.00400001" quat="0.707107 0 0 0.707107">
          <inertial pos="4.36753e-07 0.00615753 0.020911" quat="0.70703 0.0104245 0.0104245 0.70703" mass="0.033" diaginertia="6.34e-06 6.31472e-06 8.85281e-07" />
          <joint name="left_finger5_joint2" class="wuji_finger" pos="0 0 0" axis="0 1 0" range="-0.37 0.37" actuatorfrcrange="-0.1798 0.1798" />
          <geom type="mesh" contype="0" conaffinity="0" group="1" density="0" rgba="0.9 0.8 0.6 1" mesh="left_finger5_link2" />
          <geom type="mesh" rgba="0.9 0.8 0.6 1" mesh="left_finger5_link2" contype="2" conaffinity="2" />
          <body name="left_finger5_link3" pos="0 0.00475 0.0436177" quat="0.707202 0 0 -0.707012">
            <inertial pos="-0.00112188 3.28067e-05 0.0157188" quat="0.999892 0 -0.0146884 0" mass="0.0165" diaginertia="1.47088e-06 1.44e-06 4.49118e-07" />
            <joint name="left_finger5_joint3" class="wuji_finger" pos="0 0 0" axis="0 1 0" range="-0.4768 1.549" actuatorfrcrange="-0.2384 0.2384" />
            <geom type="mesh" contype="0" conaffinity="0" group="1" density="0" rgba="0.6 0.8 0.9 1" mesh="left_finger5_link3" />
            <geom type="mesh" rgba="0.6 0.8 0.9 1" mesh="left_finger5_link3" contype="1" conaffinity="1" />
            <body name="left_finger5_link4" pos="0 -0.0002 0.0295">
              <inertial pos="-0.000801156 -1.7469e-05 0.00761203" quat="0.998031 0.0128934 -0.0554374 0.0263611" mass="0.01718" diaginertia="1.55457e-06 1.45766e-06 4.20216e-07" />
              <joint name="left_finger5_joint4" class="wuji_finger" pos="0 0 0" axis="0 1 0" range="-0.4683 1.5735" actuatorfrcrange="-0.1866 0.1866" />
              <geom type="mesh" contype="0" conaffinity="0" group="1" density="0" rgba="0.6 0.8 0.9 1" mesh="left_finger5_link4" />
              <geom type="mesh" rgba="0.6 0.8 0.9 1" mesh="left_finger5_link4" contype="1" conaffinity="1" />
              <geom pos="-0.00105041 0.000201047 0.0267" type="mesh" contype="0" conaffinity="0" group="1" density="0" rgba="0.6 0.8 0.9 1" mesh="left_finger5_tip_link" />
              <geom pos="-0.00105041 0.000201047 0.0267" type="mesh" rgba="0.6 0.8 0.9 1" mesh="left_finger5_tip_link" contype="1" conaffinity="1" />
            </body>
          </body>
        </body>
      </body>
    </body>
    <body name="left_tool" pos="0 0 0">
      <site name="left_tool_site" pos="0 0 0" size="0.005"/>
    </body>
  </body>
                        </body>
                      </body>
                    </body>
                  </body>
                </body>
              </body>
            </body>
          </body>
        </body>
      </body>
      <body name="Base_R" pos="0 -0.026 1.121" quat="0.707388 0.706825 0 0">
        <inertial pos="0.00032267 4.798e-05 0.0406635" quat="0.582787 0.36644 -0.620273 0.375956" mass="1.1962" diaginertia="0.00127375 0.00107367 0.00106904"/>
        <geom class="visual"  rgba="1 0 0 1" mesh="Base_R"/>
        <geom class="collision"  rgba="1 0 0 1" mesh="Base_R"/>
        <body name="Arm_R1_Link" pos="0 0 0.1745">
          <inertial pos="2.347e-05 0.0055715 -0.03076" quat="0.711599 0.0343691 -0.0341702 0.700912" mass="1.9705" diaginertia="0.00529754 0.00492285 0.00184874"/>
          <joint name="Arm_R1_Joint" pos="0 0 0" axis="0 0 1" range="-3.1067 3.1067" actuatorfrcrange="-108 108" damping="3" armature="0.15" frictionloss="0.3"/>
          <geom class="visual"  rgba="0 1 0 1" mesh="Arm_R1_Link"/>
          <geom class="collision"  rgba="0 1 0 1" mesh="Arm_R1_Link"/>
          <body name="Arm_R2_Link" quat="0.707105 0.707108 0 0">
            <inertial pos="0.00013483 0.0617046 0.00950639" quat="0.643375 0.765551 -3.57328e-05 0.000294349" mass="2.24398" diaginertia="0.0119493 0.0112156 0.00338374"/>
            <joint name="Arm_R2_Joint" pos="0 0 0" axis="0 0 1" range="-2.0944 -0.1" actuatorfrcrange="-108 108" damping="3" armature="0.15" frictionloss="0.3"/>
            <geom class="visual"  rgba="0 0 1 1" mesh="Arm_R2_Link"/>
            <geom class="collision"  rgba="0 0 1 1" mesh="Arm_R2_Link"/>
            <body name="Arm_R3_Link" pos="0 0.287 0" quat="0.707105 -0.707108 0 0">
              <inertial pos="0.00968562 0.00246599 -0.046273" quat="0.782446 -0.0355285 -0.0735516 0.617337" mass="1.9242" diaginertia="0.00765215 0.00730789 0.0016338"/>
              <joint name="Arm_R3_Joint" pos="0 0 0" axis="0 0 1" range="-3.1067 3.1067" actuatorfrcrange="-66 66" damping="2.5" armature="0.12" frictionloss="0.25"/>
              <geom class="visual"  rgba="1 0 0 1" mesh="Arm_R3_Link"/>
              <geom class="collision"  rgba="1 0 0 1" mesh="Arm_R3_Link"/>
              <body name="Arm_R4_Link" pos="0.018 0 0" quat="-2.59734e-06 2.59735e-06 -0.707108 0.707105">
                <inertial pos="0.00850411 -0.0471822 0.00941509" quat="0.741754 0.628694 0.0774999 -0.220317" mass="1.6085" diaginertia="0.00603244 0.00535875 0.00198228"/>
                <joint name="Arm_R4_Joint" pos="0 0 0" axis="0 0 1" range="-2.5307 -0.1" actuatorfrcrange="-66 66" damping="2.5" armature="0.12" frictionloss="0.25"/>
                <geom class="visual"  rgba="0 1 0 1" mesh="Arm_R4_Link"/>
                <geom name="Arm_R4_Link_collision" class="collision"  rgba="0 1 0 1" mesh="Arm_R4_Link"/>
                <body name="Arm_R5_Link" pos="0.018 -0.314 0" quat="-2.59734e-06 2.59735e-06 -0.707108 0.707105">
                  <inertial pos="-0.00051127 -0.00101064 -0.112717" quat="0.999438 0.00995046 0.00675781 0.0312997" mass="2.0883" diaginertia="0.00626924 0.00564262 0.00243436"/>
                  <joint name="Arm_R5_Joint" pos="0 0 0" axis="0 0 1" range="-3.1067 3.1067" actuatorfrcrange="-18 18" damping="1.5" armature="0.08" frictionloss="0.15"/>
                  <geom class="visual"  rgba="0 0 1 1" mesh="Arm_R5_Link"/>
                  <geom name="Arm_R5_Link_collision" class="collision"  rgba="0 0 1 1" fromto="0 0 0 0 0 -0.15" size="0.06"/>
                  <body name="Arm_R6_Link" quat="0.499998 0.5 -0.5 0.500002">
                    <inertial pos="0.00032659 -0.00531336 0.00030182" quat="0.695472 -0.00407878 0.0225408 0.718188" mass="0.72496" diaginertia="0.000517351 0.000460362 0.000425057"/>
                    <joint name="Arm_R6_Joint" pos="0 0 0" axis="0 0 1" range="-1.0472 1.0472" actuatorfrcrange="-18 18" damping="1.2" armature="0.06" frictionloss="0.12"/>
                    <geom class="visual"  rgba="1 0 0 1" mesh="Arm_R6_Link"/>
                    <geom class="collision"  rgba="1 0 0 1" mesh="Arm_R6_Link"/>
                    <body name="Arm_R7_Link" quat="0.499998 0.5 -0.5 0.500002">
                      <inertial pos="-9.108e-05 -0.0315325 0.00889371" quat="0.84481 0.535026 0.00229584 -0.00609725" mass="0.68606" diaginertia="0.00173691 0.00153911 0.000745263"/>
                      <joint name="Arm_R7_Joint" pos="0 0 0" axis="0 0 1" range="-1.5708 1.5708" actuatorfrcrange="-18 18" damping="1.2" armature="0.05" frictionloss="0.1"/>
                      <geom class="visual"  rgba="0 1 0 1" mesh="Arm_R7_Link"/>
                      <geom class="collision"  rgba="0 1 0 1" mesh="Arm_R7_Link"/>
                      <body name="flange_R" pos="0 -0.088 0" quat="0.499998 0.5 -0.5 0.500002">
                        <body name="right_gripper_mount" pos="0 0 0" quat="0.7071068 0 0 -0.7071068">
                          <body name="right_gripper_base" pos="0 0 0">
                            <inertial pos="-0.000142 0.005641 0.0488811" mass="0.4064271" fullinertia="0.0002976 0.0004831 0.0004721 -0.0000024 0.0000011 -0.0000721"/>
                            <geom group="2" type="mesh" contype="0" conaffinity="0" material="gripper_base_mat" mesh="right_gripper_base_mesh"/>
                            <geom group="3" type="mesh" rgba="0.9373 0.2667 0.2667 1" contype="1" conaffinity="1" condim="4" friction="0.8 0.05 0.01" mesh="right_gripper_base_mesh"/>
                            <camera name="right_wrist_camera" pos="0.01 0.01 0.115" xyaxes="-1 0 0 0 0.7 0.866" fovy="105"/>
                            <body name="right_gripper_left_finger" pos="0.0516878 -0.0421084 0.0916374" quat="0.0061005 0.0025269 -0.3826751 -0.9238594">
                              <joint name="right_gripper_left_finger_joint" type="slide" axis="1 0 0" limited="true" range="0 0.05" damping="8" armature="0.01" frictionloss="0.2"/>
                              <inertial pos="-0.0166753 -0.0028108 0.0127051" mass="0.031395" fullinertia="0.0000116 0.0000048 0.0000102 -0.0000013 0 0"/>
                              <geom group="2" type="mesh" contype="0" conaffinity="0" material="gripper_finger_mat" mesh="right_gripper_left_finger_mesh"/>
                              <geom group="3" type="mesh" rgba="0.9373 0.2667 0.2667 1" contype="1" conaffinity="1" condim="4" friction="0.8 0.05 0.01" mesh="right_gripper_left_finger_mesh"/>
                            </body>
                            <body name="right_gripper_right_finger" pos="-0.07508 -0.0261034 0.1093149" quat="0.3826751 0.9238594 0.0061006 0.0025269">
                              <joint name="right_gripper_right_finger_joint" type="slide" axis="1 0 0" limited="true" range="0 0.05" damping="8" armature="0.01" frictionloss="0.2"/>
                              <inertial pos="0.0089293 -0.0028108 0.0127051" mass="0.031395" fullinertia="0.0000116 0.0000048 0.0000102 -0.0000013 0 0"/>
                              <geom group="2" type="mesh" contype="0" conaffinity="0" material="gripper_finger_mat" mesh="right_gripper_right_finger_mesh"/>
                              <geom group="3" type="mesh" rgba="0.9373 0.2667 0.2667 1" contype="1" conaffinity="1" condim="4" friction="0.8 0.05 0.01" mesh="right_gripper_right_finger_mesh"/>
                            </body>
                            <body name="right_tool" pos="0 0 0">
                              <site name="right_tool_site" pos="0 0 0" size="0.005"/>
                            </body>
                          </body>
                        </body> 
                      </body>
                    </body>
                  </body>
                </body>
              </body>
            </body>
          </body>
        </body>
      </body>
    </body>
  </worldbody>

  <actuator>
    <position name="Arm_L1_Joint" joint="Arm_L1_Joint" kp="700" kv="140" ctrlrange="-3.1067 3.1067"/>
    <position name="Arm_L2_Joint" joint="Arm_L2_Joint" kp="700" kv="140" ctrlrange="-2.0944 -0.1"/>
    <position name="Arm_L3_Joint" joint="Arm_L3_Joint" kp="650" kv="120" ctrlrange="-3.1067 3.1067"/>
    <position name="Arm_L4_Joint" joint="Arm_L4_Joint" kp="650" kv="120" ctrlrange="-2.5307 -0.1"/>
    <position name="Arm_L5_Joint" joint="Arm_L5_Joint" kp="350" kv="70" ctrlrange="-3.1067 3.1067"/>
    <position name="Arm_L6_Joint" joint="Arm_L6_Joint" kp="250" kv="50" ctrlrange="-1.0472 1.0472"/>
    <position name="Arm_L7_Joint" joint="Arm_L7_Joint" kp="250" kv="50" ctrlrange="-1.5708 1.5708"/>

    <!-- Wuji left-hand actuators (replace simple left_gripper actuator) -->
    <position name="left_finger1_joint1_actuator" joint="left_finger1_joint1" kp="0.40844710645048043" kv="0.020882010257063675" ctrlrange="0.0475 1.603" forcerange="-0.4452 0.4452" />
    <position name="left_finger1_joint2_actuator" joint="left_finger1_joint2" kp="0.6858601063643346" kv="0.030610939996373314" ctrlrange="-0.1387 0.9324" forcerange="-0.4259 0.4259" />
    <position name="left_finger1_joint3_actuator" joint="left_finger1_joint3" kp="0.2391112196099482" kv="0.010181475050560962" ctrlrange="-0.4642 1.562" forcerange="-0.1888 0.1888" />
    <position name="left_finger1_joint4_actuator" joint="left_finger1_joint4" kp="0.20736128319711747" kv="0.00909698844675045" ctrlrange="-0.4699 1.5568" forcerange="-0.1468 0.1468" />
    <position name="left_finger2_joint1_actuator" joint="left_finger2_joint1" kp="0.37352218155860073" kv="0.01882274330029718" ctrlrange="-0.1585 1.56" forcerange="-0.6188 0.6188" />
    <position name="left_finger2_joint2_actuator" joint="left_finger2_joint2" kp="0.45592448909027794" kv="0.019798167597016643" ctrlrange="-0.37 0.37" forcerange="-0.1822 0.1822" />
    <position name="left_finger2_joint3_actuator" joint="left_finger2_joint3" kp="0.24368366649522863" kv="0.010477031953162727" ctrlrange="-0.4777 1.548" forcerange="-0.2251 0.2251" />
    <position name="left_finger2_joint4_actuator" joint="left_finger2_joint4" kp="0.18026971340925335" kv="0.008240212147903584" ctrlrange="-0.4683 1.575" forcerange="-0.217 0.217" />
    <position name="left_finger3_joint1_actuator" joint="left_finger3_joint1" kp="0.3687093483646485" kv="0.01848622487024593" ctrlrange="-0.1644 1.5516" forcerange="-0.6494 0.6494" />
    <position name="left_finger3_joint2_actuator" joint="left_finger3_joint2" kp="0.4164253443634641" kv="0.018032947229953678" ctrlrange="-0.37 0.37" forcerange="-0.1827 0.1827" />
    <position name="left_finger3_joint3_actuator" joint="left_finger3_joint3" kp="0.22218607502059182" kv="0.009592200014076666" ctrlrange="-0.4739 1.551" forcerange="-0.2078 0.2078" />
    <position name="left_finger3_joint4_actuator" joint="left_finger3_joint4" kp="0.19427606072023446" kv="0.009152994605972402" ctrlrange="-0.4684 1.5745" forcerange="-0.2018 0.2018" />
    <position name="left_finger4_joint1_actuator" joint="left_finger4_joint1" kp="0.35718151495111794" kv="0.018376606800780005" ctrlrange="-0.1554 1.558" forcerange="-0.6389 0.6389" />
    <position name="left_finger4_joint2_actuator" joint="left_finger4_joint2" kp="0.42977315313086895" kv="0.01867700966212433" ctrlrange="-0.37 0.37" forcerange="-0.1832 0.1832" />
    <position name="left_finger4_joint3_actuator" joint="left_finger4_joint3" kp="0.24930151196247122" kv="0.01059512121009555" ctrlrange="-0.4765 1.5487" forcerange="-0.2249 0.2249" />
    <position name="left_finger4_joint4_actuator" joint="left_finger4_joint4" kp="0.2285032688178066" kv="0.009917602877441107" ctrlrange="-0.4777 1.563" forcerange="-0.2044 0.2044" />
    <position name="left_finger5_joint1_actuator" joint="left_finger5_joint1" kp="0.3655325975433942" kv="0.018616960278988272" ctrlrange="-0.1626 1.558" forcerange="-0.6441 0.6441" />
    <position name="left_finger5_joint2_actuator" joint="left_finger5_joint2" kp="0.41393113081120425" kv="0.018732177029667153" ctrlrange="-0.37 0.37" forcerange="-0.1798 0.1798" />
    <position name="left_finger5_joint3_actuator" joint="left_finger5_joint3" kp="0.22729367621965954" kv="0.00951005441616486" ctrlrange="-0.4768 1.549" forcerange="-0.2384 0.2384" />
    <position name="left_finger5_joint4_actuator" joint="left_finger5_joint4" kp="0.1964723550341816" kv="0.009017295241756363" ctrlrange="-0.4683 1.573" forcerange="-0.1866 0.1866" />

    <position name="Arm_R1_Joint" joint="Arm_R1_Joint" kp="700" kv="140" ctrlrange="-3.1067 3.1067"/>
    <position name="Arm_R2_Joint" joint="Arm_R2_Joint" kp="700" kv="140" ctrlrange="-2.0944 -0.1"/>
    <position name="Arm_R3_Joint" joint="Arm_R3_Joint" kp="650" kv="120" ctrlrange="-3.1067 3.1067"/>
    <position name="Arm_R4_Joint" joint="Arm_R4_Joint" kp="650" kv="120" ctrlrange="-2.5307 -0.1"/>
    <position name="Arm_R5_Joint" joint="Arm_R5_Joint" kp="350" kv="70" ctrlrange="-3.1067 3.1067"/>
    <position name="Arm_R6_Joint" joint="Arm_R6_Joint" kp="250" kv="50" ctrlrange="-1.0472 1.0472"/>
    <position name="Arm_R7_Joint" joint="Arm_R7_Joint" kp="250" kv="50" ctrlrange="-1.5708 1.5708"/>
    <position name="right_gripper" joint="right_gripper_left_finger_joint" kp="100" kv="10" ctrlrange="0 0.05" forcerange="-30 30"/>
  </actuator>

  <keyframe>
    <key name="home" qpos="1.7 -1.1 -1.1 -2 -0.37 0.13 0.55 0 0 -1.7 -1.1 1.1 -2 0.37 0.13 -0.55 0 0" ctrl="1.7 -1.1 -1.1 -2 -0.37 0.13 0.55 -1.7 -1.1 1.1 -2 0.37 0.13 -0.55 0 0"/>
  </keyframe>
</mujoco>
